Workbook
Name _Hlk156828105: Distribution!#REF!

Sheet Summary-WI
B1: Date | C1: 45808 | G1: 5 | H1: =G1+1 -> 6 | I1: =H1+1 -> 7 | J1: =I1+1 -> 8 | K1: =J1+1 -> 9 | L1: =K1+1 -> 10 | M1: =L1+1 -> 11 | N1: =M1+1 -> 12 | O1: =N1+1 -> 13 | ... AA1: =Z1+1 -> 25
J2: YTD | K2: 1 | L2: =K2+1 -> 2 | M2: =L2+1 -> 3 | N2: =M2+1 -> 4 | O2: =N2+1 -> 5 | P2: =O2+1 -> 6 | Q2: =P2+1 -> 7 | R2: =Q2+1 -> 8 | S2: =R2+1 -> 9 | ... AA2: =Z2+1 -> 17
A3: Ordering | B3: Columns | C3: Inception Date | D3: 2025 | E3: Tickers | F3: Fund Name | G3: 1 | H3: 3 | I3: 6 | J3: 5 | K3: 12 | L3: =K3+12 -> 24 | M3: =L3+12 -> 36 | N3: =M3+12 -> 48 | O3: =N3+12 -> 60 | P3: =O3+12 -> 72 | Q3: =P3+12 -> 84 | R3: =Q3+12 -> 96 | S3: =R3+12 -> 108 | ... Y3: =X3+12 -> 180 | Z3: Since Inception Annualized | AA3: Since Inception Cumulative Returns
A4: =VLOOKUP(E4,Rank!A:B,2,FALSE) -> 1 | B4: 31 | C4: 43982 | D4: HHL_A | E4: HHL | F4: =VLOOKUP(D4,Mapping!C:D,2,FALSE) -> Harvest Healthcare Leaders Income ETF | G4: =VLOOKUP($B4,Summary!$A:$X,'Summary-WI'!G$1,FALSE) -> Harvest Global REIT Leaders Income ETF | H4: =VLOOKUP($B4,Summary!$A:$X,'Summary-WI'!H$1,FALSE) -> 0.024899083 | I4: =VLOOKUP($B4,Summary!$A:$X,'Summary-WI'!I$1,FALSE) -> 0.014768331 | J4: =VLOOKUP($B4,Summary!$A:$X,'Summary-WI'!J$1,FALSE) -> 0.00074045823 | K4: =VLOOKUP($B4,Summary!$A:$X,'Summary-WI'!K$1,FALSE) -> 0.024899083 | L4: =VLOOKUP($B4,Summary!$A:$X,'Summary-WI'!L$1,FALSE) -> 0.007734841 | M4: =VLOOKUP($B4,Summary!$A:$X,'Summary-WI'!M$1,FALSE) -> 0.04351792 | N4: =VLOOKUP($B4,Summary!$A:$X,'Summary-WI'!N$1,FALSE) -> 0.0018639034 | ... Y4: =VLOOKUP($B4,Summary!$A:$X,'Summary-WI'!Y$1,FALSE)
A5: =VLOOKUP(E5,Rank!A:B,2,FALSE) -> 1 | B5: 32 | D5: HHL_B | E5: HHL | F5: =VLOOKUP(D5,Mapping!C:D,2,FALSE) -> Harvest Healthcare Leaders Income ETF | G5: =VLOOKUP($B5,Summary!$A:$X,'Summary-WI'!G$1,FALSE) -> Harvest Healthcare Leaders Income ETF | H5: =VLOOKUP($B5,Summary!$A:$X,'Summary-WI'!H$1,FALSE) -> -0.0058851041 | I5: =VLOOKUP($B5,Summary!$A:$X,'Summary-WI'!I$1,FALSE) -> 0.051257079 | J5: =VLOOKUP($B5,Summary!$A:$X,'Summary-WI'!J$1,FALSE) -> 0.15224509 | K5: =VLOOKUP($B5,Summary!$A:$X,'Summary-WI'!K$1,FALSE) -> -0.0058851041 | L5: =VLOOKUP($B5,Summary!$A:$X,'Summary-WI'!L$1,FALSE) -> 0.031648917 | M5: =VLOOKUP($B5,Summary!$A:$X,'Summary-WI'!M$1,FALSE) -> 0.050047008 | N5: =VLOOKUP($B5,Summary!$A:$X,'Summary-WI'!N$1,FALSE) -> 0.071538588 | ... Y5: =VLOOKUP($B5,Summary!$A:$X,'Summary-WI'!Y$1,FALSE)
A6: =VLOOKUP(E6,Rank!A:B,2,FALSE) -> 1 | B6: 33 | D6: HHL_U | E6: HHL | F6: =VLOOKUP(D6,Mapping!C:D,2,FALSE) -> Harvest Healthcare Leaders Income ETF | G6: =VLOOKUP($B6,Summary!$A:$X,'Summary-WI'!G$1,FALSE) -> Harvest Healthcare Leaders Income ETF | H6: =VLOOKUP($B6,Summary!$A:$X,'Summary-WI'!H$1,FALSE) -> -0.012635319 | I6: =VLOOKUP($B6,Summary!$A:$X,'Summary-WI'!I$1,FALSE) -> 0.025626558 | J6: =VLOOKUP($B6,Summary!$A:$X,'Summary-WI'!J$1,FALSE) -> 0.14239215 | K6: =VLOOKUP($B6,Summary!$A:$X,'Summary-WI'!K$1,FALSE) -> -0.012635319 | L6: =VLOOKUP($B6,Summary!$A:$X,'Summary-WI'!L$1,FALSE) -> -0.0151065 | M6: =VLOOKUP($B6,Summary!$A:$X,'Summary-WI'!M$1,FALSE) -> 0.071658577 | N6: =VLOOKUP($B6,Summary!$A:$X,'Summary-WI'!N$1,FALSE) -> 0.09218425 | ... Y6: =VLOOKUP($B6,Summary!$A:$X,'Summary-WI'!Y$1,FALSE)
A8: =VLOOKUP(E8,Rank!A:B,2,FALSE) -> 2 | B8: 26 | D8: HBL_A | E8: HBF | F8: =VLOOKUP(D8,Mapping!C:D,2,FALSE) -> Harvest Brand Leaders Plus Income ETF | G8: =VLOOKUP($B8,Summary!$A:$X,'Summary-WI'!G$1,FALSE) -> Harvest Canadian Income & Growth Fund | H8: =VLOOKUP($B8,Summary!$A:$X,'Summary-WI'!H$1,FALSE) | I8: =VLOOKUP($B8,Summary!$A:$X,'Summary-WI'!I$1,FALSE) | J8: =VLOOKUP($B8,Summary!$A:$X,'Summary-WI'!J$1,FALSE) | K8: =VLOOKUP($B8,Summary!$A:$X,'Summary-WI'!K$1,FALSE) | L8: =VLOOKUP($B8,Summary!$A:$X,'Summary-WI'!L$1,FALSE) | M8: =VLOOKUP($B8,Summary!$A:$X,'Summary-WI'!M$1,FALSE) | N8: =VLOOKUP($B8,Summary!$A:$X,'Summary-WI'!N$1,FALSE) | ... Y8: =VLOOKUP($B8,Summary!$A:$X,'Summary-WI'!Y$1,FALSE)
A9: =VLOOKUP(E9,Rank!A:B,2,FALSE) -> 2 | B9: 27 | D9: HBL_B | E9: HBF | F9: =VLOOKUP(D9,Mapping!C:D,2,FALSE) -> Harvest Brand Leaders Plus Income ETF | G9: =VLOOKUP($B9,Summary!$A:$X,'Summary-WI'!G$1,FALSE) -> Harvest Brand Leaders Plus Income ETF | H9: =VLOOKUP($B9,Summary!$A:$X,'Summary-WI'!H$1,FALSE) -> 9.3395099e-05 | I9: =VLOOKUP($B9,Summary!$A:$X,'Summary-WI'!I$1,FALSE) -> 0.0056333597 | J9: =VLOOKUP($B9,Summary!$A:$X,'Summary-WI'!J$1,FALSE) -> 0.097949563 | K9: =VLOOKUP($B9,Summary!$A:$X,'Summary-WI'!K$1,FALSE) -> 9.3395099e-05 | L9: =VLOOKUP($B9,Summary!$A:$X,'Summary-WI'!L$1,FALSE) -> 0.11805251 | M9: =VLOOKUP($B9,Summary!$A:$X,'Summary-WI'!M$1,FALSE) -> 0.14072633 | N9: =VLOOKUP($B9,Summary!$A:$X,'Summary-WI'!N$1,FALSE) -> 0.11458161 | ... Y9: =VLOOKUP($B9,Summary!$A:$X,'Summary-WI'!Y$1,FALSE)
A10: =VLOOKUP(E10,Rank!A:B,2,FALSE) -> 2 | B10: 28 | D10: HBL_U | E10: HBF | F10: =VLOOKUP(D10,Mapping!C:D,2,FALSE) -> Harvest Brand Leaders Plus Income ETF | G10: =VLOOKUP($B10,Summary!$A:$X,'Summary-WI'!G$1,FALSE) -> Harvest Brand Leaders Plus Income ETF | H10: =VLOOKUP($B10,Summary!$A:$X,'Summary-WI'!H$1,FALSE) -> -0.0063588058 | I10: =VLOOKUP($B10,Summary!$A:$X,'Summary-WI'!I$1,FALSE) -> -0.018144478 | J10: =VLOOKUP($B10,Summary!$A:$X,'Summary-WI'!J$1,FALSE) -> 0.089896494 | K10: =VLOOKUP($B10,Summary!$A:$X,'Summary-WI'!K$1,FALSE) -> -0.0063588058 | L10: =VLOOKUP($B10,Summary!$A:$X,'Summary-WI'!L$1,FALSE) -> 0.068016147 | M10: =VLOOKUP($B10,Summary!$A:$X,'Summary-WI'!M$1,FALSE) -> 0.1644338 | N10: =VLOOKUP($B10,Summary!$A:$X,'Summary-WI'!N$1,FALSE) -> 0.1368241 | ... Y10: =VLOOKUP($B10,Summary!$A:$X,'Summary-WI'!Y$1,FALSE)
A12: =VLOOKUP(E12,Rank!A:B,2,FALSE) -> 3 | B12: 3 | D12: HTA_A | E12: HTA | F12: =VLOOKUP(D12,Mapping!C:D,2,FALSE) -> Harvest Tech Achievers Growth & Income ETF | G12: =VLOOKUP($B12,Summary!$A:$X,'Summary-WI'!G$1,FALSE) -> Harvest Tech Achievers Growth & Income ETF | H12: =VLOOKUP($B12,Summary!$A:$X,'Summary-WI'!H$1,FALSE) -> 0.0039345121 | I12: =VLOOKUP($B12,Summary!$A:$X,'Summary-WI'!I$1,FALSE) -> -0.014066587 | J12: =VLOOKUP($B12,Summary!$A:$X,'Summary-WI'!J$1,FALSE) -> 0.070391771 | K12: =VLOOKUP($B12,Summary!$A:$X,'Summary-WI'!K$1,FALSE) -> 0.0039345121 | L12: =VLOOKUP($B12,Summary!$A:$X,'Summary-WI'!L$1,FALSE) -> 0.10909706 | M12: =VLOOKUP($B12,Summary!$A:$X,'Summary-WI'!M$1,FALSE) -> 0.15546626 | N12: =VLOOKUP($B12,Summary!$A:$X,'Summary-WI'!N$1,FALSE) -> 0.24714413 | ... Y12: =VLOOKUP($B12,Summary!$A:$X,'Summary-WI'!Y$1,FALSE)
A13: =VLOOKUP(E13,Rank!A:B,2,FALSE) -> 3 | B13: 4 | D13: HTA_B | E13: HTA | F13: =VLOOKUP(D13,Mapping!C:D,2,FALSE) -> Harvest Tech Achievers Growth & Income ETF | G13: =VLOOKUP($B13,Summary!$A:$X,'Summary-WI'!G$1,FALSE) -> Harvest Tech Achievers Growth & Income ETF | H13: =VLOOKUP($B13,Summary!$A:$X,'Summary-WI'!H$1,FALSE) -> -0.0022723097 | I13: =VLOOKUP($B13,Summary!$A:$X,'Summary-WI'!I$1,FALSE) -> -0.037067326 | J13: =VLOOKUP($B13,Summary!$A:$X,'Summary-WI'!J$1,FALSE) -> 0.063093209 | K13: =VLOOKUP($B13,Summary!$A:$X,'Summary-WI'!K$1,FALSE) -> -0.0022723097 | L13: =VLOOKUP($B13,Summary!$A:$X,'Summary-WI'!L$1,FALSE) -> 0.061444906 | M13: =VLOOKUP($B13,Summary!$A:$X,'Summary-WI'!M$1,FALSE) -> 0.18054652 | N13: =VLOOKUP($B13,Summary!$A:$X,'Summary-WI'!N$1,FALSE) -> 0.27238535 | ... Y13: =VLOOKUP($B13,Summary!$A:$X,'Summary-WI'!Y$1,FALSE)
A14: =VLOOKUP(E14,Rank!A:B,2,FALSE) -> 3 | B14: 5 | D14: HTA_U | E14: HTA | F14: =VLOOKUP(D14,Mapping!C:D,2,FALSE) -> Harvest Tech Achievers Growth & Income ETF | G14: =VLOOKUP($B14,Summary!$A:$X,'Summary-WI'!G$1,FALSE) -> Harvest Tech Achievers Growth & Income ETF | H14: =VLOOKUP($B14,Summary!$A:$X,'Summary-WI'!H$1,FALSE) -> 0.0057282875 | I14: =VLOOKUP($B14,Summary!$A:$X,'Summary-WI'!I$1,FALSE) -> -0.0081060304 | J14: =VLOOKUP($B14,Summary!$A:$X,'Summary-WI'!J$1,FALSE) -> 0.081823556 | K14: =VLOOKUP($B14,Summary!$A:$X,'Summary-WI'!K$1,FALSE) -> 0.0057282875 | L14: =VLOOKUP($B14,Summary!$A:$X,'Summary-WI'!L$1,FALSE) -> 0.13297781 | M14: =VLOOKUP($B14,Summary!$A:$X,'Summary-WI'!M$1,FALSE) -> 0.17310314 | N14: =VLOOKUP($B14,Summary!$A:$X,'Summary-WI'!N$1,FALSE) -> 0.26269149 | ... Y14: =VLOOKUP($B14,Summary!$A:$X,'Summary-WI'!Y$1,FALSE)
A16: =VLOOKUP(E16,Rank!A:B,2,FALSE) -> 4 | B16: 30 | D16: HGR | E16: HGR | F16: =VLOOKUP(D16,Mapping!C:D,2,FALSE) -> Harvest Global REIT Leaders Income ETF | G16: =VLOOKUP($B16,Summary!$A:$X,'Summary-WI'!G$1,FALSE) -> Harvest Global Gold Giants Index ETF | H16: =VLOOKUP($B16,Summary!$A:$X,'Summary-WI'!H$1,FALSE) -> 0.079774346 | I16: =VLOOKUP($B16,Summary!$A:$X,'Summary-WI'!I$1,FALSE) -> 0.31394586 | J16: =VLOOKUP($B16,Summary!$A:$X,'Summary-WI'!J$1,FALSE) -> 0.97695586 | K16: =VLOOKUP($B16,Summary!$A:$X,'Summary-WI'!K$1,FALSE) -> 0.079774346 | L16: =VLOOKUP($B16,Summary!$A:$X,'Summary-WI'!L$1,FALSE) -> 1.4919783 | M16: =VLOOKUP($B16,Summary!$A:$X,'Summary-WI'!M$1,FALSE) -> 1.012678 | N16: =VLOOKUP($B16,Summary!$A:$X,'Summary-WI'!N$1,FALSE) -> 0.51632314 | ... Y16: =VLOOKUP($B16,Summary!$A:$X,'Summary-WI'!Y$1,FALSE)
A18: =VLOOKUP(E18,Rank!A:B,2,FALSE) -> 5 | B18: 35 | D18: HRTM | E18: HUTL | F18: =VLOOKUP(D18,Mapping!C:D,2,FALSE) -> Harvest Equal Weight Global Utilities Income ETF | G18: =VLOOKUP($B18,Summary!$A:$X,'Summary-WI'!G$1,FALSE) -> Blockchain Technologies ETF | H18: =VLOOKUP($B18,Summary!$A:$X,'Summary-WI'!H$1,FALSE) -> 0.026827919 | I18: =VLOOKUP($B18,Summary!$A:$X,'Summary-WI'!I$1,FALSE) -> -0.26466677 | J18: =VLOOKUP($B18,Summary!$A:$X,'Summary-WI'!J$1,FALSE) -> 0.064522088 | K18: =VLOOKUP($B18,Summary!$A:$X,'Summary-WI'!K$1,FALSE) -> 0.026827919 | L18: =VLOOKUP($B18,Summary!$A:$X,'Summary-WI'!L$1,FALSE) -> 0.089636537 | M18: =VLOOKUP($B18,Summary!$A:$X,'Summary-WI'!M$1,FALSE) -> 0.28919705 | N18: =VLOOKUP($B18,Summary!$A:$X,'Summary-WI'!N$1,FALSE) -> 0.29566078 | ... Y18: =VLOOKUP($B18,Summary!$A:$X,'Summary-WI'!Y$1,FALSE)
A20: =VLOOKUP(E20,Rank!A:B,2,FALSE) -> 6 | B20: 14 | D20: HEN_A | E20: HPF | F20: =VLOOKUP(D20,Mapping!C:D,2,FALSE) -> Harvest Energy Leaders Plus Income ETF | G20: =VLOOKUP($B20,Summary!$A:$X,'Summary-WI'!G$1,FALSE) -> Harvest Canadian Equity Income Leaders ETF | H20: =VLOOKUP($B20,Summary!$A:$X,'Summary-WI'!H$1,FALSE) -> 0.020251296 | I20: =VLOOKUP($B20,Summary!$A:$X,'Summary-WI'!I$1,FALSE) -> 0.076356686 | J20: =VLOOKUP($B20,Summary!$A:$X,'Summary-WI'!J$1,FALSE) -> 0.1593143 | K20: =VLOOKUP($B20,Summary!$A:$X,'Summary-WI'!K$1,FALSE) -> 0.020251296 | L20: =VLOOKUP($B20,Summary!$A:$X,'Summary-WI'!L$1,FALSE) -> 0.27459501 | M20: =VLOOKUP($B20,Summary!$A:$X,'Summary-WI'!M$1,FALSE) -> 0.22089754 | N20: =VLOOKUP($B20,Summary!$A:$X,'Summary-WI'!N$1,FALSE) -> 0.1430029 | ... Y20: =VLOOKUP($B20,Summary!$A:$X,'Summary-WI'!Y$1,FALSE)
A21: =VLOOKUP(E21,Rank!A:B,2,FALSE) -> 6 | B21: 15 | D21: HEN_U | E21: HPF | F21: =VLOOKUP(D21,Mapping!C:D,2,FALSE) -> Harvest Energy Leaders Plus Income ETF | G21: =VLOOKUP($B21,Summary!$A:$X,'Summary-WI'!G$1,FALSE) -> Harvest Energy Leaders Plus Income ETF | H21: =VLOOKUP($B21,Summary!$A:$X,'Summary-WI'!H$1,FALSE) -> 0.090752117 | I21: =VLOOKUP($B21,Summary!$A:$X,'Summary-WI'!I$1,FALSE) -> 0.11611086 | J21: =VLOOKUP($B21,Summary!$A:$X,'Summary-WI'!J$1,FALSE) -> 0.15758369 | K21: =VLOOKUP($B21,Summary!$A:$X,'Summary-WI'!K$1,FALSE) -> 0.090752117 | L21: =VLOOKUP($B21,Summary!$A:$X,'Summary-WI'!L$1,FALSE) -> 0.1705267 | M21: =VLOOKUP($B21,Summary!$A:$X,'Summary-WI'!M$1,FALSE) -> 0.084394419 | N21: =VLOOKUP($B21,Summary!$A:$X,'Summary-WI'!N$1,FALSE) -> 0.051229043 | ... Y21: =VLOOKUP($B21,Summary!$A:$X,'Summary-WI'!Y$1,FALSE)
... A35: =VLOOKUP(E35,Rank!A:B,2,FALSE) -> 14 | B35: 43 | D35: HRVJ | E35: TBIL | F35: =VLOOKUP(D35,Mapping!C:D,2,FALSE) -> Harvest Canadian T-Bill ETF | G35: =VLOOKUP($B35,Summary!$A:$X,'Summary-WI'!G$1,FALSE) -> Harvest Travel & Leisure Income ETF | H35: =VLOOKUP($B35,Summary!$A:$X,'Summary-WI'!H$1,FALSE) -> -0.012912482 | I35: =VLOOKUP($B35,Summary!$A:$X,'Summary-WI'!I$1,FALSE) -> 0.068988412 | J35: =VLOOKUP($B35,Summary!$A:$X,'Summary-WI'!J$1,FALSE) -> 0.055809793 | K35: =VLOOKUP($B35,Summary!$A:$X,'Summary-WI'!K$1,FALSE) -> -0.012912482 | L35: =VLOOKUP($B35,Summary!$A:$X,'Summary-WI'!L$1,FALSE) -> 0.020381643 | M35: =VLOOKUP($B35,Summary!$A:$X,'Summary-WI'!M$1,FALSE) -> 0.11938376 | N35: =VLOOKUP($B35,Summary!$A:$X,'Summary-WI'!N$1,FALSE) | ... Y35: =VLOOKUP($B35,Summary!$A:$X,'Summary-WI'!Y$1,FALSE)
A37: =VLOOKUP(E37,Rank!A:B,2,FALSE) -> 28 | B37: 48 | D37: HRVL_A | E37: HPYM_A | F37: Harvest Premium Yield Treasury 7-10 Year Treasury ETF | G37: =VLOOKUP($B37,Summary!$A:$X,'Summary-WI'!G$1,FALSE) -> Big Pharma Split Corp | H37: =VLOOKUP($B37,Summary!$A:$X,'Summary-WI'!H$1,FALSE) -> 0.032924749 | I37: =VLOOKUP($B37,Summary!$A:$X,'Summary-WI'!I$1,FALSE) -> 0.1940638 | J37: =VLOOKUP($B37,Summary!$A:$X,'Summary-WI'!J$1,FALSE) -> 0.43562679 | K37: =VLOOKUP($B37,Summary!$A:$X,'Summary-WI'!K$1,FALSE) -> 0.032924749 | L37: =VLOOKUP($B37,Summary!$A:$X,'Summary-WI'!L$1,FALSE) -> 0.24952377 | M37: =VLOOKUP($B37,Summary!$A:$X,'Summary-WI'!M$1,FALSE) -> 0.11862177 | N37: =VLOOKUP($B37,Summary!$A:$X,'Summary-WI'!N$1,FALSE) -> 0.092630211 | ... Y37: =VLOOKUP($B37,Summary!$A:$X,'Summary-WI'!Y$1,FALSE)
A38: =VLOOKUP(E38,Rank!A:B,2,FALSE) -> 29 | B38: 49 | D38: HRVL_U | E38: HPYM_U | F38: Harvest Premium Yield Treasury 7-10 Year Treasury ETF | G38: =VLOOKUP($B38,Summary!$A:$X,'Summary-WI'!G$1,FALSE) -> Harvest Premium Yield Treasury 7-10 Year Treasury ETF | H38: =VLOOKUP($B38,Summary!$A:$X,'Summary-WI'!H$1,FALSE) -> -0.0021237408 | I38: =VLOOKUP($B38,Summary!$A:$X,'Summary-WI'!I$1,FALSE) -> -0.00050712575 | J38: =VLOOKUP($B38,Summary!$A:$X,'Summary-WI'!J$1,FALSE) -> 0.025946831 | K38: =VLOOKUP($B38,Summary!$A:$X,'Summary-WI'!K$1,FALSE) -> -0.0021237408 | L38: =VLOOKUP($B38,Summary!$A:$X,'Summary-WI'!L$1,FALSE) -> 0.057875352 | M38: =VLOOKUP($B38,Summary!$A:$X,'Summary-WI'!M$1,FALSE) -> 0.02137388 | N38: =VLOOKUP($B38,Summary!$A:$X,'Summary-WI'!N$1,FALSE) | ... Y38: =VLOOKUP($B38,Summary!$A:$X,'Summary-WI'!Y$1,FALSE)
A40: =VLOOKUP(E40,Rank!A:B,2,FALSE) -> 15 | B40: 6 | D40: HRA1 | E40: HHLE | F40: =VLOOKUP(D40,Mapping!C:D,2,FALSE) -> Harvest Healthcare Leaders Enhanced Income ETF | G40: =VLOOKUP($B40,Summary!$A:$X,'Summary-WI'!G$1,FALSE) -> Harvest Healthcare Leaders Enhanced Income ETF | H40: =VLOOKUP($B40,Summary!$A:$X,'Summary-WI'!H$1,FALSE) -> -0.0056687754 | I40: =VLOOKUP($B40,Summary!$A:$X,'Summary-WI'!I$1,FALSE) -> 0.059216365 | J40: =VLOOKUP($B40,Summary!$A:$X,'Summary-WI'!J$1,FALSE) -> 0.1865493 | K40: =VLOOKUP($B40,Summary!$A:$X,'Summary-WI'!K$1,FALSE) -> -0.0056687754 | L40: =VLOOKUP($B40,Summary!$A:$X,'Summary-WI'!L$1,FALSE) -> 0.023311142 | M40: =VLOOKUP($B40,Summary!$A:$X,'Summary-WI'!M$1,FALSE) -> 0.04942619 | N40: =VLOOKUP($B40,Summary!$A:$X,'Summary-WI'!N$1,FALSE) -> 0.074077154 | ... Y40: =VLOOKUP($B40,Summary!$A:$X,'Summary-WI'!Y$1,FALSE)
A42: =VLOOKUP(E42,Rank!A:B,2,FALSE) -> 16 | B42: 8 | D42: HRA3 | E42: HTAE | F42: =VLOOKUP(D42,Mapping!C:D,2,FALSE) -> Harvest Tech Achievers Enhanced Income ETF | G42: =VLOOKUP($B42,Summary!$A:$X,'Summary-WI'!G$1,FALSE) -> Harvest Tech Achievers Enhanced Income ETF | H42: =VLOOKUP($B42,Summary!$A:$X,'Summary-WI'!H$1,FALSE) -> 0.0031615072 | I42: =VLOOKUP($B42,Summary!$A:$X,'Summary-WI'!I$1,FALSE) -> -0.024408773 | J42: =VLOOKUP($B42,Summary!$A:$X,'Summary-WI'!J$1,FALSE) -> 0.082765228 | K42: =VLOOKUP($B42,Summary!$A:$X,'Summary-WI'!K$1,FALSE) -> 0.0031615072 | L42: =VLOOKUP($B42,Summary!$A:$X,'Summary-WI'!L$1,FALSE) -> 0.11535956 | M42: =VLOOKUP($B42,Summary!$A:$X,'Summary-WI'!M$1,FALSE) -> 0.17588542 | N42: =VLOOKUP($B42,Summary!$A:$X,'Summary-WI'!N$1,FALSE) -> 0.29370095 | ... Y42: =VLOOKUP($B42,Summary!$A:$X,'Summary-WI'!Y$1,FALSE)
A44: =VLOOKUP(E44,Rank!A:B,2,FALSE) -> 17 | B44: 9 | D44: HRA4 | E44: HUTE | F44: =VLOOKUP(D44,Mapping!C:D,2,FALSE) -> Harvest Equal Weight Global Utilities Enhanced Income ETF | G44: =VLOOKUP($B44,Summary!$A:$X,'Summary-WI'!G$1,FALSE) -> Harvest Equal Weight Global Utilities Enhanced Income ETF | H44: =VLOOKUP($B44,Summary!$A:$X,'Summary-WI'!H$1,FALSE) -> 0.048062951 | I44: =VLOOKUP($B44,Summary!$A:$X,'Summary-WI'!I$1,FALSE) -> 0.042974764 | J44: =VLOOKUP($B44,Summary!$A:$X,'Summary-WI'!J$1,FALSE) -> 0.082931167 | K44: =VLOOKUP($B44,Summary!$A:$X,'Summary-WI'!K$1,FALSE) -> 0.048062951 | L44: =VLOOKUP($B44,Summary!$A:$X,'Summary-WI'!L$1,FALSE) -> 0.22661672 | M44: =VLOOKUP($B44,Summary!$A:$X,'Summary-WI'!M$1,FALSE) -> 0.21329325 | N44: =VLOOKUP($B44,Summary!$A:$X,'Summary-WI'!N$1,FALSE) -> 0.1249266 | ... Y44: =VLOOKUP($B44,Summary!$A:$X,'Summary-WI'!Y$1,FALSE)
A46: =VLOOKUP(E46,Rank!A:B,2,FALSE) -> 18 | B46: 44 | D46: HRAX | E46: HDIF | F46: Harvest Diversified Monthly Income ETF | G46: =VLOOKUP($B46,Summary!$A:$X,'Summary-WI'!G$1,FALSE) -> Harvest Canadian T-Bill ETF | H46: =VLOOKUP($B46,Summary!$A:$X,'Summary-WI'!H$1,FALSE) -> 0.0017040034 | I46: =VLOOKUP($B46,Summary!$A:$X,'Summary-WI'!I$1,FALSE) -> 0.0053896465 | J46: =VLOOKUP($B46,Summary!$A:$X,'Summary-WI'!J$1,FALSE) -> 0.011726823 | K46: =VLOOKUP($B46,Summary!$A:$X,'Summary-WI'!K$1,FALSE) -> 0.0017040034 | L46: =VLOOKUP($B46,Summary!$A:$X,'Summary-WI'!L$1,FALSE) -> 0.02499132 | M46: =VLOOKUP($B46,Summary!$A:$X,'Summary-WI'!M$1,FALSE) -> 0.034299526 | N46: =VLOOKUP($B46,Summary!$A:$X,'Summary-WI'!N$1,FALSE) | ... Y46: =VLOOKUP($B46,Summary!$A:$X,'Summary-WI'!Y$1,FALSE)
A48: =VLOOKUP(E48,Rank!A:B,2,FALSE) -> 19 | B48: 29 | D48: HRTF | E48: HGGG | F48: =VLOOKUP(D48,Mapping!C:D,2,FALSE) -> Harvest Global Gold Giants Index ETF | G48: =VLOOKUP($B48,Summary!$A:$X,'Summary-WI'!G$1,FALSE) -> Harvest Brand Leaders Plus Income ETF | H48: =VLOOKUP($B48,Summary!$A:$X,'Summary-WI'!H$1,FALSE) -> 0.001602704 | I48: =VLOOKUP($B48,Summary!$A:$X,'Summary-WI'!I$1,FALSE) -> 0.011367886 | J48: =VLOOKUP($B48,Summary!$A:$X,'Summary-WI'!J$1,FALSE) -> 0.10907983 | K48: =VLOOKUP($B48,Summary!$A:$X,'Summary-WI'!K$1,FALSE) -> 0.001602704 | L48: =VLOOKUP($B48,Summary!$A:$X,'Summary-WI'!L$1,FALSE) -> 0.13998044 | M48: =VLOOKUP($B48,Summary!$A:$X,'Summary-WI'!M$1,FALSE) -> 0.15707 | N48: =VLOOKUP($B48,Summary!$A:$X,'Summary-WI'!N$1,FALSE) -> 0.12812934 | ... Y48: =VLOOKUP($B48,Summary!$A:$X,'Summary-WI'!Y$1,FALSE)
A50: =VLOOKUP(E50,Rank!A:B,2,FALSE) -> 20 | B50: 34 | D50: HRTJ | E50: HBLK | F50: =VLOOKUP(D50,Mapping!C:D,2,FALSE) -> Blockchain Technologies ETF | G50: =VLOOKUP($B50,Summary!$A:$X,'Summary-WI'!G$1,FALSE) -> Harvest Healthcare Leaders Income ETF | H50: =VLOOKUP($B50,Summary!$A:$X,'Summary-WI'!H$1,FALSE) -> -0.0047183756 | I50: =VLOOKUP($B50,Summary!$A:$X,'Summary-WI'!I$1,FALSE) -> 0.056457457 | J50: =VLOOKUP($B50,Summary!$A:$X,'Summary-WI'!J$1,FALSE) -> 0.16250828 | K50: =VLOOKUP($B50,Summary!$A:$X,'Summary-WI'!K$1,FALSE) -> -0.0047183756 | L50: =VLOOKUP($B50,Summary!$A:$X,'Summary-WI'!L$1,FALSE) -> 0.051243733 | M50: =VLOOKUP($B50,Summary!$A:$X,'Summary-WI'!M$1,FALSE) -> 0.064894941 | N50: =VLOOKUP($B50,Summary!$A:$X,'Summary-WI'!N$1,FALSE) -> 0.083843658 | ... Y50: =VLOOKUP($B50,Summary!$A:$X,'Summary-WI'!Y$1,FALSE)
A52: =VLOOKUP(E52,Rank!A:B,2,FALSE) -> 21 | B52: 39 | D52: HRTY_A | E52: TRVL | F52: =VLOOKUP(D52,Mapping!C:D,2,FALSE) -> Harvest Travel Leisure Index ETF | G52: =VLOOKUP($B52,Summary!$A:$X,'Summary-WI'!G$1,FALSE) -> Harvest Clean Energy ETF | H52: =VLOOKUP($B52,Summary!$A:$X,'Summary-WI'!H$1,FALSE) -> 0.095312438 | I52: =VLOOKUP($B52,Summary!$A:$X,'Summary-WI'!I$1,FALSE) -> 0.037057611 | J52: =VLOOKUP($B52,Summary!$A:$X,'Summary-WI'!J$1,FALSE) -> 0.27397324 | K52: =VLOOKUP($B52,Summary!$A:$X,'Summary-WI'!K$1,FALSE) -> 0.095312438 | L52: =VLOOKUP($B52,Summary!$A:$X,'Summary-WI'!L$1,FALSE) -> 0.45095172 | M52: =VLOOKUP($B52,Summary!$A:$X,'Summary-WI'!M$1,FALSE) -> 0.13229166 | N52: =VLOOKUP($B52,Summary!$A:$X,'Summary-WI'!N$1,FALSE) -> -0.054581089 | ... Y52: =VLOOKUP($B52,Summary!$A:$X,'Summary-WI'!Y$1,FALSE)
A53: =VLOOKUP(E53,Rank!A:B,2,FALSE) -> 21 | B53: 40 | D53: HRTY_U | E53: TRVL | F53: =VLOOKUP(D53,Mapping!C:D,2,FALSE) -> Harvest Travel Leisure Index ETF | G53: =VLOOKUP($B53,Summary!$A:$X,'Summary-WI'!G$1,FALSE) -> Harvest Travel Leisure Index ETF | H53: =VLOOKUP($B53,Summary!$A:$X,'Summary-WI'!H$1,FALSE) -> -0.017052328 | I53: =VLOOKUP($B53,Summary!$A:$X,'Summary-WI'!I$1,FALSE) -> 0.060401468 | J53: =VLOOKUP($B53,Summary!$A:$X,'Summary-WI'!J$1,FALSE) -> 0.050944171 | K53: =VLOOKUP($B53,Summary!$A:$X,'Summary-WI'!K$1,FALSE) -> -0.017052328 | L53: =VLOOKUP($B53,Summary!$A:$X,'Summary-WI'!L$1,FALSE) -> 0.01562815 | M53: =VLOOKUP($B53,Summary!$A:$X,'Summary-WI'!M$1,FALSE) -> 0.18006236 | N53: =VLOOKUP($B53,Summary!$A:$X,'Summary-WI'!N$1,FALSE) -> 0.17031418 | ... Y53: =VLOOKUP($B53,Summary!$A:$X,'Summary-WI'!Y$1,FALSE)
A55: =VLOOKUP(E55,Rank!A:B,2,FALSE) -> 22 | B55: 38 | D55: HRTX | E55: HCLN | F55: =VLOOKUP(D55,Mapping!C:D,2,FALSE) -> Harvest Clean Energy ETF | G55: =VLOOKUP($B55,Summary!$A:$X,'Summary-WI'!G$1,FALSE) -> Harvest US Bank Leaders Income ETF | H55: =VLOOKUP($B55,Summary!$A:$X,'Summary-WI'!H$1,FALSE) -> 0.025618787 | I55: =VLOOKUP($B55,Summary!$A:$X,'Summary-WI'!I$1,FALSE) -> 0.12575425 | J55: =VLOOKUP($B55,Summary!$A:$X,'Summary-WI'!J$1,FALSE) -> 0.15961469 | K55: =VLOOKUP($B55,Summary!$A:$X,'Summary-WI'!K$1,FALSE) -> 0.025618787 | L55: =VLOOKUP($B55,Summary!$A:$X,'Summary-WI'!L$1,FALSE) -> 0.14431258 | M55: =VLOOKUP($B55,Summary!$A:$X,'Summary-WI'!M$1,FALSE) -> 0.26661566 | N55: =VLOOKUP($B55,Summary!$A:$X,'Summary-WI'!N$1,FALSE) -> 0.10791511 | ... Y55: =VLOOKUP($B55,Summary!$A:$X,'Summary-WI'!Y$1,FALSE)
A57: =VLOOKUP(E57,Rank!A:B,2,FALSE) -> 23 | B57: 45 | D57: PRM unit | E57: PRM | F57: Big Pharm Fund | G57: =VLOOKUP($B57,Summary!$A:$X,'Summary-WI'!G$1,FALSE) -> Harvest Diversified Monthly Income ETF | H57: =VLOOKUP($B57,Summary!$A:$X,'Summary-WI'!H$1,FALSE) -> 0.0045624315 | I57: =VLOOKUP($B57,Summary!$A:$X,'Summary-WI'!I$1,FALSE) -> 0.037776627 | J57: =VLOOKUP($B57,Summary!$A:$X,'Summary-WI'!J$1,FALSE) -> 0.10627477 | K57: =VLOOKUP($B57,Summary!$A:$X,'Summary-WI'!K$1,FALSE) -> 0.0045624315 | L57: =VLOOKUP($B57,Summary!$A:$X,'Summary-WI'!L$1,FALSE) -> 0.11712546 | M57: =VLOOKUP($B57,Summary!$A:$X,'Summary-WI'!M$1,FALSE) -> 0.16619934 | N57: =VLOOKUP($B57,Summary!$A:$X,'Summary-WI'!N$1,FALSE) -> 0.13332449 | ... Y57: =VLOOKUP($B57,Summary!$A:$X,'Summary-WI'!Y$1,FALSE)
A58: =VLOOKUP(E58,Rank!A:B,2,FALSE) -> 23 | B58: 46 | D58: PRM Pref | E58: PRM | F58: Big Pharma Split Corp | G58: =VLOOKUP($B58,Summary!$A:$X,'Summary-WI'!G$1,FALSE) -> Big Pharm Fund | H58: =VLOOKUP($B58,Summary!$A:$X,'Summary-WI'!H$1,FALSE) -> 0.019210503 | I58: =VLOOKUP($B58,Summary!$A:$X,'Summary-WI'!I$1,FALSE) -> 0.11263726 | J58: =VLOOKUP($B58,Summary!$A:$X,'Summary-WI'!J$1,FALSE) -> 0.23458446 | K58: =VLOOKUP($B58,Summary!$A:$X,'Summary-WI'!K$1,FALSE) -> 0.019210503 | L58: =VLOOKUP($B58,Summary!$A:$X,'Summary-WI'!L$1,FALSE) -> 0.15934471 | M58: =VLOOKUP($B58,Summary!$A:$X,'Summary-WI'!M$1,FALSE) -> 0.088925156 | N58: =VLOOKUP($B58,Summary!$A:$X,'Summary-WI'!N$1,FALSE) -> 0.074282224 | ... Y58: =VLOOKUP($B58,Summary!$A:$X,'Summary-WI'!Y$1,FALSE)
A59: =VLOOKUP(E59,Rank!A:B,2,FALSE) -> 23 | B59: 47 | D59: PRM Class A | E59: PRM | F59: Big Pharma Split Corp Preferred class | G59: =VLOOKUP($B59,Summary!$A:$X,'Summary-WI'!G$1,FALSE) -> Big Pharma Split Corp Preferred class | H59: =VLOOKUP($B59,Summary!$A:$X,'Summary-WI'!H$1,FALSE) -> 0 | I59: =VLOOKUP($B59,Summary!$A:$X,'Summary-WI'!I$1,FALSE) -> 0.0125 | J59: =VLOOKUP($B59,Summary!$A:$X,'Summary-WI'!J$1,FALSE) -> 0.02515625 | K59: =VLOOKUP($B59,Summary!$A:$X,'Summary-WI'!K$1,FALSE) -> 0 | L59: =VLOOKUP($B59,Summary!$A:$X,'Summary-WI'!L$1,FALSE) -> 0.050945337 | M59: =VLOOKUP($B59,Summary!$A:$X,'Summary-WI'!M$1,FALSE) -> 0.050945337 | N59: =VLOOKUP($B59,Summary!$A:$X,'Summary-WI'!N$1,FALSE) -> 0.050945337 | ... Y59: =VLOOKUP($B59,Summary!$A:$X,'Summary-WI'!Y$1,FALSE)
A61: =VLOOKUP(E61,Rank!A:B,2,FALSE) -> 24 | B61: 21 | D61: HCF_I | E61: HCF | F61: =VLOOKUP(D61,Mapping!C:D,2,FALSE) -> Harvest Canadian Income & Growth Fund | G61: =VLOOKUP($B61,Summary!$A:$X,'Summary-WI'!G$1,FALSE) -> Harvest Banks & Buildings Income Fund | H61: =VLOOKUP($B61,Summary!$A:$X,'Summary-WI'!H$1,FALSE) | I61: =VLOOKUP($B61,Summary!$A:$X,'Summary-WI'!I$1,FALSE) | J61: =VLOOKUP($B61,Summary!$A:$X,'Summary-WI'!J$1,FALSE) | K61: =VLOOKUP($B61,Summary!$A:$X,'Summary-WI'!K$1,FALSE) | L61: =VLOOKUP($B61,Summary!$A:$X,'Summary-WI'!L$1,FALSE) | M61: =VLOOKUP($B61,Summary!$A:$X,'Summary-WI'!M$1,FALSE) | N61: =VLOOKUP($B61,Summary!$A:$X,'Summary-WI'!N$1,FALSE) | ... Y61: =VLOOKUP($B61,Summary!$A:$X,'Summary-WI'!Y$1,FALSE)
A62: =VLOOKUP(E62,Rank!A:B,2,FALSE) -> 24 | B62: 22 | D62: HCF_R | E62: HCF | F62: =VLOOKUP(D62,Mapping!C:D,2,FALSE) -> Harvest Canadian Income & Growth Fund | G62: =VLOOKUP($B62,Summary!$A:$X,'Summary-WI'!G$1,FALSE) -> Harvest Canadian Income & Growth Fund | H62: =VLOOKUP($B62,Summary!$A:$X,'Summary-WI'!H$1,FALSE) | I62: =VLOOKUP($B62,Summary!$A:$X,'Summary-WI'!I$1,FALSE) | J62: =VLOOKUP($B62,Summary!$A:$X,'Summary-WI'!J$1,FALSE) | K62: =VLOOKUP($B62,Summary!$A:$X,'Summary-WI'!K$1,FALSE) | L62: =VLOOKUP($B62,Summary!$A:$X,'Summary-WI'!L$1,FALSE) | M62: =VLOOKUP($B62,Summary!$A:$X,'Summary-WI'!M$1,FALSE) | N62: =VLOOKUP($B62,Summary!$A:$X,'Summary-WI'!N$1,FALSE) | ... Y62: =VLOOKUP($B62,Summary!$A:$X,'Summary-WI'!Y$1,FALSE)
A63: =VLOOKUP(E63,Rank!A:B,2,FALSE) -> 24 | B63: 23 | D63: HCF_A | E63: HCF | F63: =VLOOKUP(D63,Mapping!C:D,2,FALSE) -> Harvest Canadian Income & Growth Fund | G63: =VLOOKUP($B63,Summary!$A:$X,'Summary-WI'!G$1,FALSE) -> Harvest Canadian Income & Growth Fund | H63: =VLOOKUP($B63,Summary!$A:$X,'Summary-WI'!H$1,FALSE) | I63: =VLOOKUP($B63,Summary!$A:$X,'Summary-WI'!I$1,FALSE) | J63: =VLOOKUP($B63,Summary!$A:$X,'Summary-WI'!J$1,FALSE) | K63: =VLOOKUP($B63,Summary!$A:$X,'Summary-WI'!K$1,FALSE) | L63: =VLOOKUP($B63,Summary!$A:$X,'Summary-WI'!L$1,FALSE) | M63: =VLOOKUP($B63,Summary!$A:$X,'Summary-WI'!M$1,FALSE) | N63: =VLOOKUP($B63,Summary!$A:$X,'Summary-WI'!N$1,FALSE) | ... Y63: =VLOOKUP($B63,Summary!$A:$X,'Summary-WI'!Y$1,FALSE)
A64: =VLOOKUP(E64,Rank!A:B,2,FALSE) -> 24 | B64: 24 | D64: HCF_F | E64: HCF | F64: =VLOOKUP(D64,Mapping!C:D,2,FALSE) -> Harvest Canadian Income & Growth Fund | G64: =VLOOKUP($B64,Summary!$A:$X,'Summary-WI'!G$1,FALSE) -> Harvest Canadian Income & Growth Fund | H64: =VLOOKUP($B64,Summary!$A:$X,'Summary-WI'!H$1,FALSE) | I64: =VLOOKUP($B64,Summary!$A:$X,'Summary-WI'!I$1,FALSE) | J64: =VLOOKUP($B64,Summary!$A:$X,'Summary-WI'!J$1,FALSE) | K64: =VLOOKUP($B64,Summary!$A:$X,'Summary-WI'!K$1,FALSE) | L64: =VLOOKUP($B64,Summary!$A:$X,'Summary-WI'!L$1,FALSE) | M64: =VLOOKUP($B64,Summary!$A:$X,'Summary-WI'!M$1,FALSE) | N64: =VLOOKUP($B64,Summary!$A:$X,'Summary-WI'!N$1,FALSE) | ... Y64: =VLOOKUP($B64,Summary!$A:$X,'Summary-WI'!Y$1,FALSE)
A65: =VLOOKUP(E65,Rank!A:B,2,FALSE) -> 24 | B65: 25 | D65: HCF_D | E65: HCF | F65: =VLOOKUP(D65,Mapping!C:D,2,FALSE) -> Harvest Canadian Income & Growth Fund | G65: =VLOOKUP($B65,Summary!$A:$X,'Summary-WI'!G$1,FALSE) -> Harvest Canadian Income & Growth Fund | H65: =VLOOKUP($B65,Summary!$A:$X,'Summary-WI'!H$1,FALSE) | I65: =VLOOKUP($B65,Summary!$A:$X,'Summary-WI'!I$1,FALSE) | J65: =VLOOKUP($B65,Summary!$A:$X,'Summary-WI'!J$1,FALSE) | K65: =VLOOKUP($B65,Summary!$A:$X,'Summary-WI'!K$1,FALSE) | L65: =VLOOKUP($B65,Summary!$A:$X,'Summary-WI'!L$1,FALSE) | M65: =VLOOKUP($B65,Summary!$A:$X,'Summary-WI'!M$1,FALSE) | N65: =VLOOKUP($B65,Summary!$A:$X,'Summary-WI'!N$1,FALSE) | ... Y65: =VLOOKUP($B65,Summary!$A:$X,'Summary-WI'!Y$1,FALSE)
A67: =VLOOKUP(E67,Rank!A:B,2,FALSE) -> 25 | B67: 16 | D67: HBB_I | E67: HBB | F67: =VLOOKUP(D67,Mapping!C:D,2,FALSE) -> Harvest Banks & Buildings Income Fund | G67: =VLOOKUP($B67,Summary!$A:$X,'Summary-WI'!G$1,FALSE) -> Harvest Energy Leaders Plus Income ETF | H67: =VLOOKUP($B67,Summary!$A:$X,'Summary-WI'!H$1,FALSE) -> 0.093785781 | I67: =VLOOKUP($B67,Summary!$A:$X,'Summary-WI'!I$1,FALSE) -> 0.12866759 | J67: =VLOOKUP($B67,Summary!$A:$X,'Summary-WI'!J$1,FALSE) -> 0.16994772 | K67: =VLOOKUP($B67,Summary!$A:$X,'Summary-WI'!K$1,FALSE) -> 0.093785781 | L67: =VLOOKUP($B67,Summary!$A:$X,'Summary-WI'!L$1,FALSE) -> 0.20507303 | M67: =VLOOKUP($B67,Summary!$A:$X,'Summary-WI'!M$1,FALSE) -> 0.093110684 | N67: =VLOOKUP($B67,Summary!$A:$X,'Summary-WI'!N$1,FALSE) -> 0.058172842 | ... Y67: =VLOOKUP($B67,Summary!$A:$X,'Summary-WI'!Y$1,FALSE)
A68: =VLOOKUP(E68,Rank!A:B,2,FALSE) -> 25 | B68: 17 | D68: HBB_R | E68: HBB | F68: =VLOOKUP(D68,Mapping!C:D,2,FALSE) -> Harvest Banks & Buildings Income Fund | G68: =VLOOKUP($B68,Summary!$A:$X,'Summary-WI'!G$1,FALSE) -> Harvest Banks & Buildings Income Fund | H68: =VLOOKUP($B68,Summary!$A:$X,'Summary-WI'!H$1,FALSE) | I68: =VLOOKUP($B68,Summary!$A:$X,'Summary-WI'!I$1,FALSE) | J68: =VLOOKUP($B68,Summary!$A:$X,'Summary-WI'!J$1,FALSE) | K68: =VLOOKUP($B68,Summary!$A:$X,'Summary-WI'!K$1,FALSE) | L68: =VLOOKUP($B68,Summary!$A:$X,'Summary-WI'!L$1,FALSE) | M68: =VLOOKUP($B68,Summary!$A:$X,'Summary-WI'!M$1,FALSE) | N68: =VLOOKUP($B68,Summary!$A:$X,'Summary-WI'!N$1,FALSE) | ... Y68: =VLOOKUP($B68,Summary!$A:$X,'Summary-WI'!Y$1,FALSE)
A69: =VLOOKUP(E69,Rank!A:B,2,FALSE) -> 25 | B69: 18 | D69: HBB_A | E69: HBB | F69: =VLOOKUP(D69,Mapping!C:D,2,FALSE) -> Harvest Banks & Buildings Income Fund | G69: =VLOOKUP($B69,Summary!$A:$X,'Summary-WI'!G$1,FALSE) -> Harvest Banks & Buildings Income Fund | H69: =VLOOKUP($B69,Summary!$A:$X,'Summary-WI'!H$1,FALSE) | I69: =VLOOKUP($B69,Summary!$A:$X,'Summary-WI'!I$1,FALSE) | J69: =VLOOKUP($B69,Summary!$A:$X,'Summary-WI'!J$1,FALSE) | K69: =VLOOKUP($B69,Summary!$A:$X,'Summary-WI'!K$1,FALSE) | L69: =VLOOKUP($B69,Summary!$A:$X,'Summary-WI'!L$1,FALSE) | M69: =VLOOKUP($B69,Summary!$A:$X,'Summary-WI'!M$1,FALSE) | N69: =VLOOKUP($B69,Summary!$A:$X,'Summary-WI'!N$1,FALSE) | ... Y69: =VLOOKUP($B69,Summary!$A:$X,'Summary-WI'!Y$1,FALSE)
A70: =VLOOKUP(E70,Rank!A:B,2,FALSE) -> 25 | B70: 19 | D70: HBB_F | E70: HBB | F70: =VLOOKUP(D70,Mapping!C:D,2,FALSE) -> Harvest Banks & Buildings Income Fund | G70: =VLOOKUP($B70,Summary!$A:$X,'Summary-WI'!G$1,FALSE) -> Harvest Banks & Buildings Income Fund | H70: =VLOOKUP($B70,Summary!$A:$X,'Summary-WI'!H$1,FALSE) | I70: =VLOOKUP($B70,Summary!$A:$X,'Summary-WI'!I$1,FALSE) | J70: =VLOOKUP($B70,Summary!$A:$X,'Summary-WI'!J$1,FALSE) | K70: =VLOOKUP($B70,Summary!$A:$X,'Summary-WI'!K$1,FALSE) | L70: =VLOOKUP($B70,Summary!$A:$X,'Summary-WI'!L$1,FALSE) | M70: =VLOOKUP($B70,Summary!$A:$X,'Summary-WI'!M$1,FALSE) | N70: =VLOOKUP($B70,Summary!$A:$X,'Summary-WI'!N$1,FALSE) | ... Y70: =VLOOKUP($B70,Summary!$A:$X,'Summary-WI'!Y$1,FALSE)
...

Sheet Rank
A1: HHL | B1: 1
A2: HBF | B2: =B1+1 -> 2
A3: HTA | B3: =B2+1 -> 3
A4: HGR | B4: =B3+1 -> 4
A5: HUTL | B5: =B4+1 -> 5
A6: HPF | B6: =B5+1 -> 6
A7: HUBL | B7: =B6+1 -> 7
A8: HLIF | B8: =B7+1 -> 8
A9: TRVI | B9: =B8+1 -> 9
A10: HRIF | B10: =B9+1 -> 10
A11: HIND | B11: =B10+1 -> 11
A12: HPYT | B12: =B11+1 -> 12
A13: HPYM | B13: =B12+1 -> 13
... A31: HLFE | B31: =B30+1 -> 31

Sheet Summary
I1: YTD | J1: 1 | K1: =J1+1 -> 2 | L1: =K1+1 -> 3 | M1: =L1+1 -> 4 | N1: =M1+1 -> 5 | O1: =N1+1 -> 6 | P1: =O1+1 -> 7 | Q1: =P1+1 -> 8 | R1: =Q1+1 -> 9 | ... X1: =W1+1 -> 15
A2: Columns | B2: Helper column for Benchmark | C2: 2026 | D2: Tickers | E2: Fund Name | F2: 1 | G2: 3 | H2: 6 | I2: 1 | J2: 12 | K2: =J2+12 -> 24 | L2: =K2+12 -> 36 | M2: =L2+12 -> 48 | N2: =M2+12 -> 60 | O2: =N2+12 -> 72 | P2: =O2+12 -> 84 | Q2: =P2+12 -> 96 | R2: =Q2+12 -> 108 | ... X2: =W2+12 -> 180 | Y2: Since Inception Return Cumulative | Z2: Since Inception Return Annualized
A3: 3 | C3: HR21_A | D3: HTA | E3: Harvest Tech Achievers Growth & Income ETF | F3: =IFERROR(VLOOKUP(F$2,'R.WEALTH-Cummulative'!$A:$FG,$A3,FALSE)-1,"") -> 0.0039345121 | G3: =IFERROR(VLOOKUP(G$2,'R.WEALTH-Cummulative'!$A:$FG,$A3,FALSE)-1,"") -> -0.014066587 | H3: =IFERROR(VLOOKUP(H$2,'R.WEALTH-Cummulative'!$A:$FG,$A3,FALSE)-1,"") -> 0.070391771 | I3: =IFERROR(VLOOKUP(I$2,'R.WEALTH-Cummulative'!$A:$FG,$A3,FALSE)-1,"") -> 0.0039345121 | J3: =IFERROR(VLOOKUP(J$2,'R.WEALTH-Cummulative'!$A:$FG,$A3,FALSE)-1,"") -> 0.10909706 | K3: =IFERROR((VLOOKUP(K$2,'R.WEALTH-Cummulative'!$A:$FG,$A3,FALSE)^(1/(K$2/12)))-1,"") -> 0.15546626 | L3: =IFERROR((VLOOKUP(L$2,'R.WEALTH-Cummulative'!$A:$FG,$A3,FALSE)^(1/(L$2/12)))-1,"") -> 0.24714413 | M3: =IFERROR((VLOOKUP(M$2,'R.WEALTH-Cummulative'!$A:$FG,$A3,FALSE)^(1/(M$2/12)))-1,"") -> 0.12274083 | N3: =IFERROR((VLOOKUP(N$2,'R.WEALTH-Cummulative'!$A:$FG,$A3,FALSE)^(1/(N$2/12)))-1,"") -> 0.1564718 | O3: =IFERROR((VLOOKUP(O$2,'R.WEALTH-Cummulative'!$A:$FG,$A3,FALSE)^(1/(O$2/12)))-1,"") -> 0.173751 | P3: =IFERROR((VLOOKUP(P$2,'R.WEALTH-Cummulative'!$A:$FG,$A3,FALSE)^(1/(P$2/12)))-1,"") -> 0.1885161 | Q3: =IFERROR((VLOOKUP(Q$2,'R.WEALTH-Cummulative'!$A:$FG,$A3,FALSE)^(1/(Q$2/12)))-1,"") -> 0.16206241 | R3: =IFERROR((VLOOKUP(R$2,'R.WEALTH-Cummulative'!$A:$FG,$A3,FALSE)^(1/(R$2/12)))-1,"") -> 0.18055081 | ... X3: =IFERROR((VLOOKUP(X$2,'R.WEALTH-Cummulative'!$A:$FG,$A3,FALSE)^(1/(X$2/12)))-1,"") | Y3: =VLOOKUP(Y$2,'Since Inception Returns'!$B:$AAB,Summary!A3-1,FALSE) -> 3.6241408 | Z3: =VLOOKUP(Z$2,'Since Inception Returns'!$B:$AAB,Summary!A3-1,FALSE) -> 0.15416579
B4: 3 | C4: HR21_A | D4: HTA | E4: Solactive US Large & Mid Cap Technology Index NTR | F4: =IFERROR(VLOOKUP(F$2,'R.WEALTH-Cummulative (BM)'!$A:$FH,$B4,FALSE)-1,"") -> -0.0092134294 | G4: =IFERROR(VLOOKUP(G$2,'R.WEALTH-Cummulative (BM)'!$A:$FH,$B4,FALSE)-1,"") -> -0.040381701 | H4: =IFERROR(VLOOKUP(H$2,'R.WEALTH-Cummulative (BM)'!$A:$FH,$B4,FALSE)-1,"") -> 0.081863367 | I4: =IFERROR(VLOOKUP(I$2,'R.WEALTH-Cummulative (BM)'!$A:$FH,$B4,FALSE)-1,"") -> -0.0092134294 | J4: =IFERROR(VLOOKUP(J$2,'R.WEALTH-Cummulative (BM)'!$A:$FH,$B4,FALSE)-1,"") -> 0.22829774 | K4: =IFERROR((VLOOKUP(K$2,'R.WEALTH-Cummulative (BM)'!$A:$FH,$B4,FALSE)^(1/(K$2/12)))-1,"") -> 0.27251111 | L4: =IFERROR((VLOOKUP(L$2,'R.WEALTH-Cummulative (BM)'!$A:$FH,$B4,FALSE)^(1/(L$2/12)))-1,"") -> 0.33824538 | M4: =IFERROR((VLOOKUP(M$2,'R.WEALTH-Cummulative (BM)'!$A:$FH,$B4,FALSE)^(1/(M$2/12)))-1,"") -> 0.17552657 | N4: =IFERROR((VLOOKUP(N$2,'R.WEALTH-Cummulative (BM)'!$A:$FH,$B4,FALSE)^(1/(N$2/12)))-1,"") -> 0.18267576 | O4: =IFERROR((VLOOKUP(O$2,'R.WEALTH-Cummulative (BM)'!$A:$FH,$B4,FALSE)^(1/(O$2/12)))-1,"") -> 0.21648671 | P4: =IFERROR((VLOOKUP(P$2,'R.WEALTH-Cummulative (BM)'!$A:$FH,$B4,FALSE)^(1/(P$2/12)))-1,"") -> 0.2402506 | Q4: =IFERROR((VLOOKUP(Q$2,'R.WEALTH-Cummulative (BM)'!$A:$FH,$B4,FALSE)^(1/(Q$2/12)))-1,"") -> 0.2095893 | R4: =IFERROR((VLOOKUP(R$2,'R.WEALTH-Cummulative (BM)'!$A:$FH,$B4,FALSE)^(1/(R$2/12)))-1,"") -> 0.23284223 | ... X4: =IFERROR((VLOOKUP(X$2,'R.WEALTH-Cummulative (BM)'!$A:$FH,$B4,FALSE)^(1/(X$2/12)))-1,"") | Y4: =VLOOKUP(Y$2,'Since Inception (BM)'!$B:$AAC,Summary!B4-1,FALSE) -> 6.8725103 | Z4: =VLOOKUP(Z$2,'Since Inception (BM)'!$B:$AAC,Summary!B4-1,FALSE) -> 0.21312315
A5: 4 | C5: HR21_B | D5: HTA.B | E5: Harvest Tech Achievers Growth & Income ETF | F5: =IFERROR(VLOOKUP(F$2,'R.WEALTH-Cummulative'!$A:$FG,$A5,FALSE)-1,"") -> -0.0022723097 | G5: =IFERROR(VLOOKUP(G$2,'R.WEALTH-Cummulative'!$A:$FG,$A5,FALSE)-1,"") -> -0.037067326 | H5: =IFERROR(VLOOKUP(H$2,'R.WEALTH-Cummulative'!$A:$FG,$A5,FALSE)-1,"") -> 0.063093209 | I5: =IFERROR(VLOOKUP(I$2,'R.WEALTH-Cummulative'!$A:$FG,$A5,FALSE)-1,"") -> -0.0022723097 | J5: =IFERROR(VLOOKUP(J$2,'R.WEALTH-Cummulative'!$A:$FG,$A5,FALSE)-1,"") -> 0.061444906 | K5: =IFERROR((VLOOKUP(K$2,'R.WEALTH-Cummulative'!$A:$FG,$A5,FALSE)^(1/(K$2/12)))-1,"") -> 0.18054652 | L5: =IFERROR((VLOOKUP(L$2,'R.WEALTH-Cummulative'!$A:$FG,$A5,FALSE)^(1/(L$2/12)))-1,"") -> 0.27238535 | M5: =IFERROR((VLOOKUP(M$2,'R.WEALTH-Cummulative'!$A:$FG,$A5,FALSE)^(1/(M$2/12)))-1,"") -> 0.15736247 | N5: =IFERROR((VLOOKUP(N$2,'R.WEALTH-Cummulative'!$A:$FG,$A5,FALSE)^(1/(N$2/12)))-1,"") -> 0.18413194 | O5: =IFERROR((VLOOKUP(O$2,'R.WEALTH-Cummulative'!$A:$FG,$A5,FALSE)^(1/(O$2/12)))-1,"") | P5: =IFERROR((VLOOKUP(P$2,'R.WEALTH-Cummulative'!$A:$FG,$A5,FALSE)^(1/(P$2/12)))-1,"") | Q5: =IFERROR((VLOOKUP(Q$2,'R.WEALTH-Cummulative'!$A:$FG,$A5,FALSE)^(1/(Q$2/12)))-1,"") | R5: =IFERROR((VLOOKUP(R$2,'R.WEALTH-Cummulative'!$A:$FG,$A5,FALSE)^(1/(R$2/12)))-1,"") | ... X5: =IFERROR((VLOOKUP(X$2,'R.WEALTH-Cummulative'!$A:$FG,$A5,FALSE)^(1/(X$2/12)))-1,"") | Y5: =VLOOKUP(Y$2,'Since Inception Returns'!$B:$AAB,Summary!A5-1,FALSE) -> 2.0543982 | Z5: =VLOOKUP(Z$2,'Since Inception Returns'!$B:$AAB,Summary!A5-1,FALSE) -> 0.20874123
B6: 4 | C6: HR21_B | D6: HTA.B | E6: Solactive US Large & Mid Cap Technology Index NTR | F6: =IFERROR(VLOOKUP(F$2,'R.WEALTH-Cummulative (BM)'!$A:$FH,$B6,FALSE)-1,"") -> -0.0092134294 | G6: =IFERROR(VLOOKUP(G$2,'R.WEALTH-Cummulative (BM)'!$A:$FH,$B6,FALSE)-1,"") -> -0.040381701 | H6: =IFERROR(VLOOKUP(H$2,'R.WEALTH-Cummulative (BM)'!$A:$FH,$B6,FALSE)-1,"") -> 0.081863367 | I6: =IFERROR(VLOOKUP(I$2,'R.WEALTH-Cummulative (BM)'!$A:$FH,$B6,FALSE)-1,"") -> -0.0092134294 | J6: =IFERROR(VLOOKUP(J$2,'R.WEALTH-Cummulative (BM)'!$A:$FH,$B6,FALSE)-1,"") -> 0.22829774 | K6: =IFERROR((VLOOKUP(K$2,'R.WEALTH-Cummulative (BM)'!$A:$FH,$B6,FALSE)^(1/(K$2/12)))-1,"") -> 0.27251111 | L6: =IFERROR((VLOOKUP(L$2,'R.WEALTH-Cummulative (BM)'!$A:$FH,$B6,FALSE)^(1/(L$2/12)))-1,"") -> 0.33824538 | M6: =IFERROR((VLOOKUP(M$2,'R.WEALTH-Cummulative (BM)'!$A:$FH,$B6,FALSE)^(1/(M$2/12)))-1,"") -> 0.17552657 | N6: =IFERROR((VLOOKUP(N$2,'R.WEALTH-Cummulative (BM)'!$A:$FH,$B6,FALSE)^(1/(N$2/12)))-1,"") -> 0.18267576 | O6: =IFERROR((VLOOKUP(O$2,'R.WEALTH-Cummulative (BM)'!$A:$FH,$B6,FALSE)^(1/(O$2/12)))-1,"") | P6: =IFERROR((VLOOKUP(P$2,'R.WEALTH-Cummulative (BM)'!$A:$FH,$B6,FALSE)^(1/(P$2/12)))-1,"") | Q6: =IFERROR((VLOOKUP(Q$2,'R.WEALTH-Cummulative (BM)'!$A:$FH,$B6,FALSE)^(1/(Q$2/12)))-1,"") | R6: =IFERROR((VLOOKUP(R$2,'R.WEALTH-Cummulative (BM)'!$A:$FH,$B6,FALSE)^(1/(R$2/12)))-1,"") | ... X6: =IFERROR((VLOOKUP(X$2,'R.WEALTH-Cummulative (BM)'!$A:$FH,$B6,FALSE)^(1/(X$2/12)))-1,"") | Y6: =VLOOKUP(Y$2,'Since Inception (BM)'!$B:$AAC,Summary!B6-1,FALSE) -> 2.539619 | Z6: =VLOOKUP(Z$2,'Since Inception (BM)'!$B:$AAC,Summary!B6-1,FALSE) -> 0.23938104
A7: 5 | C7: HR21_U | D7: HTA.U | E7: Harvest Tech Achievers Growth & Income ETF | F7: =IFERROR(VLOOKUP(F$2,'R.WEALTH-Cummulative'!$A:$FG,$A7,FALSE)-1,"") -> 0.0057282875 | G7: =IFERROR(VLOOKUP(G$2,'R.WEALTH-Cummulative'!$A:$FG,$A7,FALSE)-1,"") -> -0.0081060304 | H7: =IFERROR(VLOOKUP(H$2,'R.WEALTH-Cummulative'!$A:$FG,$A7,FALSE)-1,"") -> 0.081823556 | I7: =IFERROR(VLOOKUP(I$2,'R.WEALTH-Cummulative'!$A:$FG,$A7,FALSE)-1,"") -> 0.0057282875 | J7: =IFERROR(VLOOKUP(J$2,'R.WEALTH-Cummulative'!$A:$FG,$A7,FALSE)-1,"") -> 0.13297781 | K7: =IFERROR((VLOOKUP(K$2,'R.WEALTH-Cummulative'!$A:$FG,$A7,FALSE)^(1/(K$2/12)))-1,"") -> 0.17310314 | L7: =IFERROR((VLOOKUP(L$2,'R.WEALTH-Cummulative'!$A:$FG,$A7,FALSE)^(1/(L$2/12)))-1,"") -> 0.26269149 | M7: =IFERROR((VLOOKUP(M$2,'R.WEALTH-Cummulative'!$A:$FG,$A7,FALSE)^(1/(M$2/12)))-1,"") -> 0.13764182 | N7: =IFERROR((VLOOKUP(N$2,'R.WEALTH-Cummulative'!$A:$FG,$A7,FALSE)^(1/(N$2/12)))-1,"") -> 0.16936137 | O7: =IFERROR((VLOOKUP(O$2,'R.WEALTH-Cummulative'!$A:$FG,$A7,FALSE)^(1/(O$2/12)))-1,"") -> 0.18965347 | P7: =IFERROR((VLOOKUP(P$2,'R.WEALTH-Cummulative'!$A:$FG,$A7,FALSE)^(1/(P$2/12)))-1,"") -> 0.2036496 | Q7: =IFERROR((VLOOKUP(Q$2,'R.WEALTH-Cummulative'!$A:$FG,$A7,FALSE)^(1/(Q$2/12)))-1,"") -> 0.1759251 | R7: =IFERROR((VLOOKUP(R$2,'R.WEALTH-Cummulative'!$A:$FG,$A7,FALSE)^(1/(R$2/12)))-1,"") | ... X7: =IFERROR((VLOOKUP(X$2,'R.WEALTH-Cummulative'!$A:$FG,$A7,FALSE)^(1/(X$2/12)))-1,"") | Y7: =VLOOKUP(Y$2,'Since Inception Returns'!$B:$AAB,Summary!A7-1,FALSE) -> 3.3673596 | Z7: =VLOOKUP(Z$2,'Since Inception Returns'!$B:$AAB,Summary!A7-1,FALSE) -> 0.18665379
B8: 5 | C8: HR21_U | D8: HTA.U | E8: Solactive US Large & Mid Cap Technology Index NTR | F8: =IFERROR(VLOOKUP(F$2,'R.WEALTH-Cummulative (BM)'!$A:$FH,$B8,FALSE)-1,"") -> -0.0092134294 | G8: =IFERROR(VLOOKUP(G$2,'R.WEALTH-Cummulative (BM)'!$A:$FH,$B8,FALSE)-1,"") -> -0.040381701 | H8: =IFERROR(VLOOKUP(H$2,'R.WEALTH-Cummulative (BM)'!$A:$FH,$B8,FALSE)-1,"") -> 0.081863367 | I8: =IFERROR(VLOOKUP(I$2,'R.WEALTH-Cummulative (BM)'!$A:$FH,$B8,FALSE)-1,"") -> -0.0092134294 | J8: =IFERROR(VLOOKUP(J$2,'R.WEALTH-Cummulative (BM)'!$A:$FH,$B8,FALSE)-1,"") -> 0.22829774 | K8: =IFERROR((VLOOKUP(K$2,'R.WEALTH-Cummulative (BM)'!$A:$FH,$B8,FALSE)^(1/(K$2/12)))-1,"") -> 0.27251111 | L8: =IFERROR((VLOOKUP(L$2,'R.WEALTH-Cummulative (BM)'!$A:$FH,$B8,FALSE)^(1/(L$2/12)))-1,"") -> 0.33824538 | M8: =IFERROR((VLOOKUP(M$2,'R.WEALTH-Cummulative (BM)'!$A:$FH,$B8,FALSE)^(1/(M$2/12)))-1,"") -> 0.17552657 | N8: =IFERROR((VLOOKUP(N$2,'R.WEALTH-Cummulative (BM)'!$A:$FH,$B8,FALSE)^(1/(N$2/12)))-1,"") -> 0.18267576 | O8: =IFERROR((VLOOKUP(O$2,'R.WEALTH-Cummulative (BM)'!$A:$FH,$B8,FALSE)^(1/(O$2/12)))-1,"") -> 0.21648671 | P8: =IFERROR((VLOOKUP(P$2,'R.WEALTH-Cummulative (BM)'!$A:$FH,$B8,FALSE)^(1/(P$2/12)))-1,"") -> 0.2402506 | Q8: =IFERROR((VLOOKUP(Q$2,'R.WEALTH-Cummulative (BM)'!$A:$FH,$B8,FALSE)^(1/(Q$2/12)))-1,"") -> 0.2095893 | R8: =IFERROR((VLOOKUP(R$2,'R.WEALTH-Cummulative (BM)'!$A:$FH,$B8,FALSE)^(1/(R$2/12)))-1,"") | ... X8: =IFERROR((VLOOKUP(X$2,'R.WEALTH-Cummulative (BM)'!$A:$FH,$B8,FALSE)^(1/(X$2/12)))-1,"") | Y8: =VLOOKUP(Y$2,'Since Inception (BM)'!$B:$AAC,Summary!B8-1,FALSE) -> 4.7405742 | Z8: =VLOOKUP(Z$2,'Since Inception (BM)'!$B:$AAC,Summary!B8-1,FALSE) -> 0.22492169
A9: 6 | C9: HRA1 | D9: HHLE | E9: Harvest Healthcare Leaders Enhanced Income ETF | F9: =IFERROR(VLOOKUP(F$2,'R.WEALTH-Cummulative'!$A:$FG,$A9,FALSE)-1,"") -> -0.0056687754 | G9: =IFERROR(VLOOKUP(G$2,'R.WEALTH-Cummulative'!$A:$FG,$A9,FALSE)-1,"") -> 0.059216365 | H9: =IFERROR(VLOOKUP(H$2,'R.WEALTH-Cummulative'!$A:$FG,$A9,FALSE)-1,"") -> 0.1865493 | I9: =IFERROR(VLOOKUP(I$2,'R.WEALTH-Cummulative'!$A:$FG,$A9,FALSE)-1,"") -> -0.0056687754 | J9: =IFERROR(VLOOKUP(J$2,'R.WEALTH-Cummulative'!$A:$FG,$A9,FALSE)-1,"") -> 0.023311142 | K9: =IFERROR((VLOOKUP(K$2,'R.WEALTH-Cummulative'!$A:$FG,$A9,FALSE)^(1/(K$2/12)))-1,"") -> 0.04942619 | L9: =IFERROR((VLOOKUP(L$2,'R.WEALTH-Cummulative'!$A:$FG,$A9,FALSE)^(1/(L$2/12)))-1,"") -> 0.074077154 | M9: =IFERROR((VLOOKUP(M$2,'R.WEALTH-Cummulative'!$A:$FG,$A9,FALSE)^(1/(M$2/12)))-1,"") | N9: =IFERROR((VLOOKUP(N$2,'R.WEALTH-Cummulative'!$A:$FG,$A9,FALSE)^(1/(N$2/12)))-1,"") | O9: =IFERROR((VLOOKUP(O$2,'R.WEALTH-Cummulative'!$A:$FG,$A9,FALSE)^(1/(O$2/12)))-1,"") | P9: =IFERROR((VLOOKUP(P$2,'R.WEALTH-Cummulative'!$A:$FG,$A9,FALSE)^(1/(P$2/12)))-1,"") | Q9: =IFERROR((VLOOKUP(Q$2,'R.WEALTH-Cummulative'!$A:$FG,$A9,FALSE)^(1/(Q$2/12)))-1,"") | R9: =IFERROR((VLOOKUP(R$2,'R.WEALTH-Cummulative'!$A:$FG,$A9,FALSE)^(1/(R$2/12)))-1,"") | ... X9: =IFERROR((VLOOKUP(X$2,'R.WEALTH-Cummulative'!$A:$FG,$A9,FALSE)^(1/(X$2/12)))-1,"") | Y9: =VLOOKUP(Y$2,'Since Inception Returns'!$B:$AAB,Summary!A9-1,FALSE) -> 0.31530969 | Z9: =VLOOKUP(Z$2,'Since Inception Returns'!$B:$AAB,Summary!A9-1,FALSE) -> 0.087145106
B10: 6 | C10: HRA1 | D10: HHLE | E10: MSCI World Health Care Net Total Return USD Index | F10: =IFERROR(VLOOKUP(F$2,'R.WEALTH-Cummulative (BM)'!$A:$FH,$B10,FALSE)-1,"") -> 0.010953014 | G10: =IFERROR(VLOOKUP(G$2,'R.WEALTH-Cummulative (BM)'!$A:$FH,$B10,FALSE)-1,"") -> 0.084428037 | H10: =IFERROR(VLOOKUP(H$2,'R.WEALTH-Cummulative (BM)'!$A:$FH,$B10,FALSE)-1,"") -> 0.18692932 | I10: =IFERROR(VLOOKUP(I$2,'R.WEALTH-Cummulative (BM)'!$A:$FH,$B10,FALSE)-1,"") -> 0.010953014 | J10: =IFERROR(VLOOKUP(J$2,'R.WEALTH-Cummulative (BM)'!$A:$FH,$B10,FALSE)-1,"") -> 0.091091301 | K10: =IFERROR((VLOOKUP(K$2,'R.WEALTH-Cummulative (BM)'!$A:$FH,$B10,FALSE)^(1/(K$2/12)))-1,"") -> 0.069243604 | L10: =IFERROR((VLOOKUP(L$2,'R.WEALTH-Cummulative (BM)'!$A:$FH,$B10,FALSE)^(1/(L$2/12)))-1,"") -> 0.0702882 | M10: =IFERROR((VLOOKUP(M$2,'R.WEALTH-Cummulative (BM)'!$A:$FH,$B10,FALSE)^(1/(M$2/12)))-1,"") | N10: =IFERROR((VLOOKUP(N$2,'R.WEALTH-Cummulative (BM)'!$A:$FH,$B10,FALSE)^(1/(N$2/12)))-1,"") | O10: =IFERROR((VLOOKUP(O$2,'R.WEALTH-Cummulative (BM)'!$A:$FH,$B10,FALSE)^(1/(O$2/12)))-1,"") | P10: =IFERROR((VLOOKUP(P$2,'R.WEALTH-Cummulative (BM)'!$A:$FH,$B10,FALSE)^(1/(P$2/12)))-1,"") | Q10: =IFERROR((VLOOKUP(Q$2,'R.WEALTH-Cummulative (BM)'!$A:$FH,$B10,FALSE)^(1/(Q$2/12)))-1,"") | R10: =IFERROR((VLOOKUP(R$2,'R.WEALTH-Cummulative (BM)'!$A:$FH,$B10,FALSE)^(1/(R$2/12)))-1,"") | ... X10: =IFERROR((VLOOKUP(X$2,'R.WEALTH-Cummulative (BM)'!$A:$FH,$B10,FALSE)^(1/(X$2/12)))-1,"") | Y10: =VLOOKUP(Y$2,'Since Inception (BM)'!$B:$AAC,Summary!B10-1,FALSE) -> 0.35399402 | Z10: =VLOOKUP(Z$2,'Since Inception (BM)'!$B:$AAC,Summary!B10-1,FALSE) -> 0.096794795
A11: 7 | C11: #N/A | D11: #N/A | E11: Harvest Brand Leaders Enhanced Income ETF | F11: =IFERROR(VLOOKUP(F$2,'R.WEALTH-Cummulative'!$A:$FG,$A11,FALSE)-1,"") | G11: =IFERROR(VLOOKUP(G$2,'R.WEALTH-Cummulative'!$A:$FG,$A11,FALSE)-1,"") | H11: =IFERROR(VLOOKUP(H$2,'R.WEALTH-Cummulative'!$A:$FG,$A11,FALSE)-1,"") | I11: =IFERROR(VLOOKUP(I$2,'R.WEALTH-Cummulative'!$A:$FG,$A11,FALSE)-1,"") | J11: =IFERROR(VLOOKUP(J$2,'R.WEALTH-Cummulative'!$A:$FG,$A11,FALSE)-1,"") | K11: =IFERROR((VLOOKUP(K$2,'R.WEALTH-Cummulative'!$A:$FG,$A11,FALSE)^(1/(K$2/12)))-1,"") | L11: =IFERROR((VLOOKUP(L$2,'R.WEALTH-Cummulative'!$A:$FG,$A11,FALSE)^(1/(L$2/12)))-1,"") | M11: =IFERROR((VLOOKUP(M$2,'R.WEALTH-Cummulative'!$A:$FG,$A11,FALSE)^(1/(M$2/12)))-1,"") | N11: =IFERROR((VLOOKUP(N$2,'R.WEALTH-Cummulative'!$A:$FG,$A11,FALSE)^(1/(N$2/12)))-1,"") | O11: =IFERROR((VLOOKUP(O$2,'R.WEALTH-Cummulative'!$A:$FG,$A11,FALSE)^(1/(O$2/12)))-1,"") | P11: =IFERROR((VLOOKUP(P$2,'R.WEALTH-Cummulative'!$A:$FG,$A11,FALSE)^(1/(P$2/12)))-1,"") | Q11: =IFERROR((VLOOKUP(Q$2,'R.WEALTH-Cummulative'!$A:$FG,$A11,FALSE)^(1/(Q$2/12)))-1,"") | R11: =IFERROR((VLOOKUP(R$2,'R.WEALTH-Cummulative'!$A:$FG,$A11,FALSE)^(1/(R$2/12)))-1,"") | ... X11: =IFERROR((VLOOKUP(X$2,'R.WEALTH-Cummulative'!$A:$FG,$A11,FALSE)^(1/(X$2/12)))-1,"") | Y11: =VLOOKUP(Y$2,'Since Inception Returns'!$B:$AAB,Summary!A11-1,FALSE) -> 0.28924112 | Z11: =VLOOKUP(Z$2,'Since Inception Returns'!$B:$AAB,Summary!A11-1,FALSE) -> 0.1494006
A12: 8 | C12: HRA3 | D12: HTAE | E12: Harvest Tech Achievers Enhanced Income ETF | F12: =IFERROR(VLOOKUP(F$2,'R.WEALTH-Cummulative'!$A:$FG,$A12,FALSE)-1,"") -> 0.0031615072 | G12: =IFERROR(VLOOKUP(G$2,'R.WEALTH-Cummulative'!$A:$FG,$A12,FALSE)-1,"") -> -0.024408773 | H12: =IFERROR(VLOOKUP(H$2,'R.WEALTH-Cummulative'!$A:$FG,$A12,FALSE)-1,"") -> 0.082765228 | I12: =IFERROR(VLOOKUP(I$2,'R.WEALTH-Cummulative'!$A:$FG,$A12,FALSE)-1,"") -> 0.0031615072 | J12: =IFERROR(VLOOKUP(J$2,'R.WEALTH-Cummulative'!$A:$FG,$A12,FALSE)-1,"") -> 0.11535956 | K12: =IFERROR((VLOOKUP(K$2,'R.WEALTH-Cummulative'!$A:$FG,$A12,FALSE)^(1/(K$2/12)))-1,"") -> 0.17588542 | L12: =IFERROR((VLOOKUP(L$2,'R.WEALTH-Cummulative'!$A:$FG,$A12,FALSE)^(1/(L$2/12)))-1,"") -> 0.29370095 | M12: =IFERROR((VLOOKUP(M$2,'R.WEALTH-Cummulative'!$A:$FG,$A12,FALSE)^(1/(M$2/12)))-1,"") | N12: =IFERROR((VLOOKUP(N$2,'R.WEALTH-Cummulative'!$A:$FG,$A12,FALSE)^(1/(N$2/12)))-1,"") | O12: =IFERROR((VLOOKUP(O$2,'R.WEALTH-Cummulative'!$A:$FG,$A12,FALSE)^(1/(O$2/12)))-1,"") | P12: =IFERROR((VLOOKUP(P$2,'R.WEALTH-Cummulative'!$A:$FG,$A12,FALSE)^(1/(P$2/12)))-1,"") | Q12: =IFERROR((VLOOKUP(Q$2,'R.WEALTH-Cummulative'!$A:$FG,$A12,FALSE)^(1/(Q$2/12)))-1,"") | R12: =IFERROR((VLOOKUP(R$2,'R.WEALTH-Cummulative'!$A:$FG,$A12,FALSE)^(1/(R$2/12)))-1,"") | ... X12: =IFERROR((VLOOKUP(X$2,'R.WEALTH-Cummulative'!$A:$FG,$A12,FALSE)^(1/(X$2/12)))-1,"") | Y12: =VLOOKUP(Y$2,'Since Inception Returns'!$B:$AAB,Summary!A12-1,FALSE) -> 1.4200677 | Z12: =VLOOKUP(Z$2,'Since Inception Returns'!$B:$AAB,Summary!A12-1,FALSE) -> 0.30922925
B13: 8 | C13: HRA3 | D13: HTAE | E13: Solactive US Large & Mid Cap Technology Index NTR | F13: =IFERROR(VLOOKUP(F$2,'R.WEALTH-Cummulative (BM)'!$A:$FH,$B13,FALSE)-1,"") -> -0.0092134294 | G13: =IFERROR(VLOOKUP(G$2,'R.WEALTH-Cummulative (BM)'!$A:$FH,$B13,FALSE)-1,"") -> -0.040381701 | H13: =IFERROR(VLOOKUP(H$2,'R.WEALTH-Cummulative (BM)'!$A:$FH,$B13,FALSE)-1,"") -> 0.081863367 | I13: =IFERROR(VLOOKUP(I$2,'R.WEALTH-Cummulative (BM)'!$A:$FH,$B13,FALSE)-1,"") -> -0.0092134294 | J13: =IFERROR(VLOOKUP(J$2,'R.WEALTH-Cummulative (BM)'!$A:$FH,$B13,FALSE)-1,"") -> 0.22829774 | K13: =IFERROR((VLOOKUP(K$2,'R.WEALTH-Cummulative (BM)'!$A:$FH,$B13,FALSE)^(1/(K$2/12)))-1,"") -> 0.27251111 | L13: =IFERROR((VLOOKUP(L$2,'R.WEALTH-Cummulative (BM)'!$A:$FH,$B13,FALSE)^(1/(L$2/12)))-1,"") -> 0.33824538 | M13: =IFERROR((VLOOKUP(M$2,'R.WEALTH-Cummulative (BM)'!$A:$FH,$B13,FALSE)^(1/(M$2/12)))-1,"") | N13: =IFERROR((VLOOKUP(N$2,'R.WEALTH-Cummulative (BM)'!$A:$FH,$B13,FALSE)^(1/(N$2/12)))-1,"") | O13: =IFERROR((VLOOKUP(O$2,'R.WEALTH-Cummulative (BM)'!$A:$FH,$B13,FALSE)^(1/(O$2/12)))-1,"") | P13: =IFERROR((VLOOKUP(P$2,'R.WEALTH-Cummulative (BM)'!$A:$FH,$B13,FALSE)^(1/(P$2/12)))-1,"") | Q13: =IFERROR((VLOOKUP(Q$2,'R.WEALTH-Cummulative (BM)'!$A:$FH,$B13,FALSE)^(1/(Q$2/12)))-1,"") | R13: =IFERROR((VLOOKUP(R$2,'R.WEALTH-Cummulative (BM)'!$A:$FH,$B13,FALSE)^(1/(R$2/12)))-1,"") | ... X13: =IFERROR((VLOOKUP(X$2,'R.WEALTH-Cummulative (BM)'!$A:$FH,$B13,FALSE)^(1/(X$2/12)))-1,"") | Y13: =VLOOKUP(Y$2,'Since Inception (BM)'!$B:$AAC,Summary!B13-1,FALSE) -> 1.6486322 | Z13: =VLOOKUP(Z$2,'Since Inception (BM)'!$B:$AAC,Summary!B13-1,FALSE) -> 0.34575075
A14: 9 | C14: HRA4 | D14: HUTE | E14: Harvest Equal Weight Global Utilities Enhanced Income ETF | F14: =IFERROR(VLOOKUP(F$2,'R.WEALTH-Cummulative'!$A:$FG,$A14,FALSE)-1,"") -> 0.048062951 | G14: =IFERROR(VLOOKUP(G$2,'R.WEALTH-Cummulative'!$A:$FG,$A14,FALSE)-1,"") -> 0.042974764 | H14: =IFERROR(VLOOKUP(H$2,'R.WEALTH-Cummulative'!$A:$FG,$A14,FALSE)-1,"") -> 0.082931167 | I14: =IFERROR(VLOOKUP(I$2,'R.WEALTH-Cummulative'!$A:$FG,$A14,FALSE)-1,"") -> 0.048062951 | J14: =IFERROR(VLOOKUP(J$2,'R.WEALTH-Cummulative'!$A:$FG,$A14,FALSE)-1,"") -> 0.22661672 | K14: =IFERROR((VLOOKUP(K$2,'R.WEALTH-Cummulative'!$A:$FG,$A14,FALSE)^(1/(K$2/12)))-1,"") -> 0.21329325 | L14: =IFERROR((VLOOKUP(L$2,'R.WEALTH-Cummulative'!$A:$FG,$A14,FALSE)^(1/(L$2/12)))-1,"") -> 0.1249266 | M14: =IFERROR((VLOOKUP(M$2,'R.WEALTH-Cummulative'!$A:$FG,$A14,FALSE)^(1/(M$2/12)))-1,"") | N14: =IFERROR((VLOOKUP(N$2,'R.WEALTH-Cummulative'!$A:$FG,$A14,FALSE)^(1/(N$2/12)))-1,"") | O14: =IFERROR((VLOOKUP(O$2,'R.WEALTH-Cummulative'!$A:$FG,$A14,FALSE)^(1/(O$2/12)))-1,"") | P14: =IFERROR((VLOOKUP(P$2,'R.WEALTH-Cummulative'!$A:$FG,$A14,FALSE)^(1/(P$2/12)))-1,"") | Q14: =IFERROR((VLOOKUP(Q$2,'R.WEALTH-Cummulative'!$A:$FG,$A14,FALSE)^(1/(Q$2/12)))-1,"") | R14: =IFERROR((VLOOKUP(R$2,'R.WEALTH-Cummulative'!$A:$FG,$A14,FALSE)^(1/(R$2/12)))-1,"") | ... X14: =IFERROR((VLOOKUP(X$2,'R.WEALTH-Cummulative'!$A:$FG,$A14,FALSE)^(1/(X$2/12)))-1,"") | Y14: =VLOOKUP(Y$2,'Since Inception Returns'!$B:$AAB,Summary!A14-1,FALSE) -> 0.57573137 | Z14: =VLOOKUP(Z$2,'Since Inception Returns'!$B:$AAB,Summary!A14-1,FALSE) -> 0.14869695
B15: 9 | C15: HRA4 | D15: HUTE | E15: MSCI World Utilities GRTR Local Index | F15: =IFERROR(VLOOKUP(F$2,'R.WEALTH-Cummulative (BM)'!$A:$FH,$B15,FALSE)-1,"") -> 0.03314887 | G15: =IFERROR(VLOOKUP(G$2,'R.WEALTH-Cummulative (BM)'!$A:$FH,$B15,FALSE)-1,"") -> 0.021324403 | H15: =IFERROR(VLOOKUP(H$2,'R.WEALTH-Cummulative (BM)'!$A:$FH,$B15,FALSE)-1,"") -> 0.082156746 | I15: =IFERROR(VLOOKUP(I$2,'R.WEALTH-Cummulative (BM)'!$A:$FH,$B15,FALSE)-1,"") -> 0.03314887 | J15: =IFERROR(VLOOKUP(J$2,'R.WEALTH-Cummulative (BM)'!$A:$FH,$B15,FALSE)-1,"") -> 0.22844476 | K15: =IFERROR((VLOOKUP(K$2,'R.WEALTH-Cummulative (BM)'!$A:$FH,$B15,FALSE)^(1/(K$2/12)))-1,"") -> 0.22649441 | L15: =IFERROR((VLOOKUP(L$2,'R.WEALTH-Cummulative (BM)'!$A:$FH,$B15,FALSE)^(1/(L$2/12)))-1,"") -> 0.13749448 | M15: =IFERROR((VLOOKUP(M$2,'R.WEALTH-Cummulative (BM)'!$A:$FH,$B15,FALSE)^(1/(M$2/12)))-1,"") | N15: =IFERROR((VLOOKUP(N$2,'R.WEALTH-Cummulative (BM)'!$A:$FH,$B15,FALSE)^(1/(N$2/12)))-1,"") | O15: =IFERROR((VLOOKUP(O$2,'R.WEALTH-Cummulative (BM)'!$A:$FH,$B15,FALSE)^(1/(O$2/12)))-1,"") | P15: =IFERROR((VLOOKUP(P$2,'R.WEALTH-Cummulative (BM)'!$A:$FH,$B15,FALSE)^(1/(P$2/12)))-1,"") | Q15: =IFERROR((VLOOKUP(Q$2,'R.WEALTH-Cummulative (BM)'!$A:$FH,$B15,FALSE)^(1/(Q$2/12)))-1,"") | R15: =IFERROR((VLOOKUP(R$2,'R.WEALTH-Cummulative (BM)'!$A:$FH,$B15,FALSE)^(1/(R$2/12)))-1,"") | ... X15: =IFERROR((VLOOKUP(X$2,'R.WEALTH-Cummulative (BM)'!$A:$FH,$B15,FALSE)^(1/(X$2/12)))-1,"") | Y15: =VLOOKUP(Y$2,'Since Inception (BM)'!$B:$AAC,Summary!B15-1,FALSE) -> 0.6574588 | Z15: =VLOOKUP(Z$2,'Since Inception (BM)'!$B:$AAC,Summary!B15-1,FALSE) -> 0.16654227
A16: 10 | C16: #N/A | D16: #N/A | E16: Harvest Canadian Equity Enhanced Income Leaders ETF | F16: =IFERROR(VLOOKUP(F$2,'R.WEALTH-Cummulative'!$A:$FG,$A16,FALSE)-1,"") | G16: =IFERROR(VLOOKUP(G$2,'R.WEALTH-Cummulative'!$A:$FG,$A16,FALSE)-1,"") | H16: =IFERROR(VLOOKUP(H$2,'R.WEALTH-Cummulative'!$A:$FG,$A16,FALSE)-1,"") | I16: =IFERROR(VLOOKUP(I$2,'R.WEALTH-Cummulative'!$A:$FG,$A16,FALSE)-1,"") | J16: =IFERROR(VLOOKUP(J$2,'R.WEALTH-Cummulative'!$A:$FG,$A16,FALSE)-1,"") | K16: =IFERROR((VLOOKUP(K$2,'R.WEALTH-Cummulative'!$A:$FG,$A16,FALSE)^(1/(K$2/12)))-1,"") | L16: =IFERROR((VLOOKUP(L$2,'R.WEALTH-Cummulative'!$A:$FG,$A16,FALSE)^(1/(L$2/12)))-1,"") | M16: =IFERROR((VLOOKUP(M$2,'R.WEALTH-Cummulative'!$A:$FG,$A16,FALSE)^(1/(M$2/12)))-1,"") | N16: =IFERROR((VLOOKUP(N$2,'R.WEALTH-Cummulative'!$A:$FG,$A16,FALSE)^(1/(N$2/12)))-1,"") | O16: =IFERROR((VLOOKUP(O$2,'R.WEALTH-Cummulative'!$A:$FG,$A16,FALSE)^(1/(O$2/12)))-1,"") | P16: =IFERROR((VLOOKUP(P$2,'R.WEALTH-Cummulative'!$A:$FG,$A16,FALSE)^(1/(P$2/12)))-1,"") | Q16: =IFERROR((VLOOKUP(Q$2,'R.WEALTH-Cummulative'!$A:$FG,$A16,FALSE)^(1/(Q$2/12)))-1,"") | R16: =IFERROR((VLOOKUP(R$2,'R.WEALTH-Cummulative'!$A:$FG,$A16,FALSE)^(1/(R$2/12)))-1,"") | ... X16: =IFERROR((VLOOKUP(X$2,'R.WEALTH-Cummulative'!$A:$FG,$A16,FALSE)^(1/(X$2/12)))-1,"") | Y16: =VLOOKUP(Y$2,'Since Inception Returns'!$B:$AAB,Summary!A16-1,FALSE) -> 0.59264257 | Z16: =VLOOKUP(Z$2,'Since Inception Returns'!$B:$AAB,Summary!A16-1,FALSE) -> 0.30683702
A17: 11 | C17: HRAS_A | D17: HPYT | E17: Harvest Premium Yield Treasury ETF | F17: =IFERROR(VLOOKUP(F$2,'R.WEALTH-Cummulative'!$A:$FG,$A17,FALSE)-1,"") -> 0.000566365 | G17: =IFERROR(VLOOKUP(G$2,'R.WEALTH-Cummulative'!$A:$FG,$A17,FALSE)-1,"") -> -0.019413517 | H17: =IFERROR(VLOOKUP(H$2,'R.WEALTH-Cummulative'!$A:$FG,$A17,FALSE)-1,"") -> 0.024874894 | I17: =IFERROR(VLOOKUP(I$2,'R.WEALTH-Cummulative'!$A:$FG,$A17,FALSE)-1,"") -> 0.000566365 | J17: =IFERROR(VLOOKUP(J$2,'R.WEALTH-Cummulative'!$A:$FG,$A17,FALSE)-1,"") -> 0.040381713 | K17: =IFERROR((VLOOKUP(K$2,'R.WEALTH-Cummulative'!$A:$FG,$A17,FALSE)^(1/(K$2/12)))-1,"") -> -0.001758294 | L17: =IFERROR((VLOOKUP(L$2,'R.WEALTH-Cummulative'!$A:$FG,$A17,FALSE)^(1/(L$2/12)))-1,"") | M17: =IFERROR((VLOOKUP(M$2,'R.WEALTH-Cummulative'!$A:$FG,$A17,FALSE)^(1/(M$2/12)))-1,"") | N17: =IFERROR((VLOOKUP(N$2,'R.WEALTH-Cummulative'!$A:$FG,$A17,FALSE)^(1/(N$2/12)))-1,"") | O17: =IFERROR((VLOOKUP(O$2,'R.WEALTH-Cummulative'!$A:$FG,$A17,FALSE)^(1/(O$2/12)))-1,"") | P17: =IFERROR((VLOOKUP(P$2,'R.WEALTH-Cummulative'!$A:$FG,$A17,FALSE)^(1/(P$2/12)))-1,"") | Q17: =IFERROR((VLOOKUP(Q$2,'R.WEALTH-Cummulative'!$A:$FG,$A17,FALSE)^(1/(Q$2/12)))-1,"") | R17: =IFERROR((VLOOKUP(R$2,'R.WEALTH-Cummulative'!$A:$FG,$A17,FALSE)^(1/(R$2/12)))-1,"") | ... X17: =IFERROR((VLOOKUP(X$2,'R.WEALTH-Cummulative'!$A:$FG,$A17,FALSE)^(1/(X$2/12)))-1,"") | Y17: =VLOOKUP(Y$2,'Since Inception Returns'!$B:$AAB,Summary!A17-1,FALSE) -> 0.02998578 | Z17: =VLOOKUP(Z$2,'Since Inception Returns'!$B:$AAB,Summary!A17-1,FALSE) -> 0.012682701
B18: 11 | C18: HRAS_A | D18: HPYT | E18: Blended Benchmark | F18: =IFERROR(VLOOKUP(F$2,'R.WEALTH-Cummulative (BM)'!$A:$FH,$B18,FALSE)-1,"") -> -0.0030880429 | G18: =IFERROR(VLOOKUP(G$2,'R.WEALTH-Cummulative (BM)'!$A:$FH,$B18,FALSE)-1,"") -> -0.015273725 | H18: =IFERROR(VLOOKUP(H$2,'R.WEALTH-Cummulative (BM)'!$A:$FH,$B18,FALSE)-1,"") -> 0.016363147 | I18: =IFERROR(VLOOKUP(I$2,'R.WEALTH-Cummulative (BM)'!$A:$FH,$B18,FALSE)-1,"") -> -0.0030880429 | J18: =IFERROR(VLOOKUP(J$2,'R.WEALTH-Cummulative (BM)'!$A:$FH,$B18,FALSE)-1,"") -> 0.032995417 | K18: =IFERROR((VLOOKUP(K$2,'R.WEALTH-Cummulative (BM)'!$A:$FH,$B18,FALSE)^(1/(K$2/12)))-1,"") -> -0.0081200165 | L18: =IFERROR((VLOOKUP(L$2,'R.WEALTH-Cummulative (BM)'!$A:$FH,$B18,FALSE)^(1/(L$2/12)))-1,"") | M18: =IFERROR((VLOOKUP(M$2,'R.WEALTH-Cummulative (BM)'!$A:$FH,$B18,FALSE)^(1/(M$2/12)))-1,"") | N18: =IFERROR((VLOOKUP(N$2,'R.WEALTH-Cummulative (BM)'!$A:$FH,$B18,FALSE)^(1/(N$2/12)))-1,"") | O18: =IFERROR((VLOOKUP(O$2,'R.WEALTH-Cummulative (BM)'!$A:$FH,$B18,FALSE)^(1/(O$2/12)))-1,"") | P18: =IFERROR((VLOOKUP(P$2,'R.WEALTH-Cummulative (BM)'!$A:$FH,$B18,FALSE)^(1/(P$2/12)))-1,"") | Q18: =IFERROR((VLOOKUP(Q$2,'R.WEALTH-Cummulative (BM)'!$A:$FH,$B18,FALSE)^(1/(Q$2/12)))-1,"") | R18: =IFERROR((VLOOKUP(R$2,'R.WEALTH-Cummulative (BM)'!$A:$FH,$B18,FALSE)^(1/(R$2/12)))-1,"") | ... X18: =IFERROR((VLOOKUP(X$2,'R.WEALTH-Cummulative (BM)'!$A:$FH,$B18,FALSE)^(1/(X$2/12)))-1,"") | Y18: =VLOOKUP(Y$2,'Since Inception (BM)'!$B:$AAC,Summary!B18-1,FALSE) -> 0.052313757 | Z18: =VLOOKUP(Z$2,'Since Inception (BM)'!$B:$AAC,Summary!B18-1,FALSE) -> 0.021989546
A19: 12 | C19: HRAS_B | D19: HPYT.B | E19: Harvest Premium Yield Treasury ETF | F19: =IFERROR(VLOOKUP(F$2,'R.WEALTH-Cummulative'!$A:$FG,$A19,FALSE)-1,"") -> -0.0061671012 | G19: =IFERROR(VLOOKUP(G$2,'R.WEALTH-Cummulative'!$A:$FG,$A19,FALSE)-1,"") -> -0.04417953 | H19: =IFERROR(VLOOKUP(H$2,'R.WEALTH-Cummulative'!$A:$FG,$A19,FALSE)-1,"") -> 0.01610936 | I19: =IFERROR(VLOOKUP(I$2,'R.WEALTH-Cummulative'!$A:$FG,$A19,FALSE)-1,"") -> -0.0061671012 | J19: =IFERROR(VLOOKUP(J$2,'R.WEALTH-Cummulative'!$A:$FG,$A19,FALSE)-1,"") -> -0.0092368358 | K19: =IFERROR((VLOOKUP(K$2,'R.WEALTH-Cummulative'!$A:$FG,$A19,FALSE)^(1/(K$2/12)))-1,"") | L19: =IFERROR((VLOOKUP(L$2,'R.WEALTH-Cummulative'!$A:$FG,$A19,FALSE)^(1/(L$2/12)))-1,"") | M19: =IFERROR((VLOOKUP(M$2,'R.WEALTH-Cummulative'!$A:$FG,$A19,FALSE)^(1/(M$2/12)))-1,"") | N19: =IFERROR((VLOOKUP(N$2,'R.WEALTH-Cummulative'!$A:$FG,$A19,FALSE)^(1/(N$2/12)))-1,"") | O19: =IFERROR((VLOOKUP(O$2,'R.WEALTH-Cummulative'!$A:$FG,$A19,FALSE)^(1/(O$2/12)))-1,"") | P19: =IFERROR((VLOOKUP(P$2,'R.WEALTH-Cummulative'!$A:$FG,$A19,FALSE)^(1/(P$2/12)))-1,"") | Q19: =IFERROR((VLOOKUP(Q$2,'R.WEALTH-Cummulative'!$A:$FG,$A19,FALSE)^(1/(Q$2/12)))-1,"") | R19: =IFERROR((VLOOKUP(R$2,'R.WEALTH-Cummulative'!$A:$FG,$A19,FALSE)^(1/(R$2/12)))-1,"") | ... X19: =IFERROR((VLOOKUP(X$2,'R.WEALTH-Cummulative'!$A:$FG,$A19,FALSE)^(1/(X$2/12)))-1,"") | Y19: =VLOOKUP(Y$2,'Since Inception Returns'!$B:$AAB,Summary!A19-1,FALSE) -> 0.036365764 | Z19: =VLOOKUP(Z$2,'Since Inception Returns'!$B:$AAB,Summary!A19-1,FALSE) -> 0.022044939
